Workbook

Sheet INVOICE
A3: TAX INVOICE
A4: BILL FROM | C4: Bill Date | D4: 45797
A5: 24 Seven Innovative products and services | C5: INVOICE No. | D5: MB1/S046/25-26
A6: Raaga Residency Plot No.782,Road No.44, | C6: GST Number | D6: 36AACFZ0539P1ZN
A7: Flat No-103 Ayyappa Society Madhapur | C7: LUT/Bond No | D7: AD3603250311498
A8: Hyderabad-500081 | C8: ESI CODE No | D8: 52000748150000900
A9: GST: 36AACFZ0539P1ZN | C9: PF CODE No | D9: APHYD2055855000
A10: BILL TO | C10: Work Order No. | D10: WO/DNIPL/B1&B2/2024-25/D326
A11: Divyasree NSL lnfrastructure Pvt Ltd, | C11: Work Order Date | D11: 25.03.2025
A12: Survey No.56/1, Serilingampalli (Mandal) | C12: Delivery Challan No's | D12: -
A13: Raidurgam, R.R.Dist, | C13: MSME Registration No | D13: TS02E0063727
A14: Hyderabad - 500032.
A15: GST: 36AACCD3662N1ZD
A16: DESCRIPTION | B16: SAC code | C16: Quantity | D16: Amount Rs.
A17: Man Power Supply for Apr-2025
A18: B1 Building
A19: Technical Executive | B19: 998519 | C19: ='INVOICE BREAKUP'!H6 -> 1 | D19: =VLOOKUP(A19,'INVOICE BREAKUP'!D$6:R$17,15,0) -> 40950.144
A20: Technical Supervisor | B20: 998519 | C20: ='INVOICE BREAKUP'!H7 -> 10 | D20: =VLOOKUP(A20,'INVOICE BREAKUP'!D$6:R$17,15,0) -> 233128.09
A21: HVAC Technician | B21: 998519 | C21: ='INVOICE BREAKUP'!H9 -> 7 | D21: =VLOOKUP(A21,'INVOICE BREAKUP'!D$6:R$17,15,0) -> 193454.77
A22: Plumber | B22: 998519 | C22: ='INVOICE BREAKUP'!H12 -> 8 | D22: =VLOOKUP(A22,'INVOICE BREAKUP'!D$6:R$17,15,0) -> 167309.22
A23: BMS Technician | B23: 998519 | C23: ='INVOICE BREAKUP'!H10 -> 4 | D23: =VLOOKUP(A23,'INVOICE BREAKUP'!D$6:R$17,15,0) -> 77822.307
A24: Electrician | B24: 998519 | C24: ='INVOICE BREAKUP'!H8 -> 8 | D24: =VLOOKUP(A24,'INVOICE BREAKUP'!D$6:R$17,15,0) -> 220516.79
A25: DG Operator | B25: 998519 | C25: ='INVOICE BREAKUP'!H11 -> 4 | D25: =VLOOKUP(A25,'INVOICE BREAKUP'!D$6:R$17,15,0) -> 106960.46
A26: Mason | B26: 998519 | C26: 1 | D26: =VLOOKUP(A26,'INVOICE BREAKUP'!D$6:R$17,15,0) -> 27139.896
A27: Painter | B27: 998519 | C27: 1 | D27: =VLOOKUP(A27,'INVOICE BREAKUP'!D$6:R$17,15,0) -> 27139.896
A28: Welder | B28: 998519 | C28: 1 | D28: =VLOOKUP(A28,'INVOICE BREAKUP'!D$6:R$17,15,0) -> 25950.015
A29: Carpenter | B29: 998519 | C29: 1 | D29: =VLOOKUP(A29,'INVOICE BREAKUP'!D$6:R$17,15,0) -> 23603.071
A30: Sub-Total | C30: =SUM(C19:C29) -> 46 | D30: =SUM(D19:D29) -> 1143974.7
A31: Management fee @8 % | D31: =D30*8% -> 91517.972
D32: =D30+D31 -> 1235492.6
A33: Tools & Tackles Rental Per Month | D33: ='INVOICE BREAKUP'!#REF! -> #REF!
A34: Uniform Charges Per Month | C34: =(PAYSHEET!F71+PAYSHEET!G71)/30 -> 43.833333 | D34: =C34*330 -> 14465
A35: Total Rs. | D35: =SUM(D32:D34) -> #REF!
B36: IGST @ | C36: 18% | D36: 0
A37: Total Amount Rs. | D37: =D35+D36 -> #REF! | F37: =D37-'INVOICE BREAKUP'!R22 -> #REF!
A39: DECLRACTION: SUPPLY TO SEZ UNIT FOR AUTHORISED OPERATIONS UNDER LUT WITHOUT PAYMENT OF INTEGRATED TAX.
A41: Bank Details : | B41: FOR 24 SEVEN INNOVATIVE PRODUCTS AND SERVICES
A42: M/S. 24 Seven Innovative Products And Services
A43: Bank name : ICICI Bank
A44: Bank account no :004005017980
...

Sheet ATTENDANCE
A1: 24SIPS O&M Attendance Report of July-26
A2: S.NO | B2: EMP.CODE | C2: NAME | D2: BIO METRIC CODE | E2: Designation | F2: Duty | G2: 1 | H2: 2 | I2: 3 | J2: 4 | K2: 5 | L2: 6 | M2: 7 | N2: 8 | O2: 9 | P2: 10 | Q2: 11 | R2: 12 | S2: 13 | T2: 14 | U2: 15 | V2: 16 | W2: 17 | X2: 18 | Y2: 19 | Z2: 20 | AA2: 21 | AB2: 22 | AC2: 23 | AD2: 24 | AE2: 25 | AF2: 26 | AG2: 27 | AH2: 28 | AI2: 29 | AJ2: 30 | AK2: 31 | AL2: A | AM2: B | AN2: C | AO2: G | AP2: W | AQ2: ED | AR2: PH | AS2: Total
G3: Wed | H3: Thu | I3: Fri | J3: Sat | K3: Sun | L3: Mon | M3: Tue | N3: Wed | O3: Thu | P3: Fri | Q3: Sat | R3: Sun | S3: Mon | T3: Tue | U3: Wed | V3: Thu | W3: Fri | X3: Sat | Y3: Sun | Z3: Mon | AA3: Tue | AB3: Wed | AC3: Thu | AD3: Fri | AE3: Sat | AF3: Sun | AG3: Mon | AH3: Tue | AI3: Wed | AJ3: Thu | AK3: Fri
A4: 1 | B4: 11029 | C4: SUDHIR KUMAR RAUTARAY | D4: 10602 | E4: TECH EXECUTIVE | F4: Duty | G4: G | H4: G | I4: G | J4: G | K4: G | L4: G | M4: W | N4: G | O4: G | P4: G | Q4: G | R4: G | S4: G | T4: W | U4: G | V4: G | W4: G | X4: G | Y4: G | Z4: G | AA4: W | AB4: G | AC4: G | AD4: G | AE4: G | AF4: G | AG4: G | AH4: W | AI4: G | AJ4: G | AK4: G | AL4: =SUM(COUNTIFS(G4:AK4,"A")) -> 0 | AM4: =SUM(COUNTIFS(G4:AK4,"B")) -> 0 | AN4: =SUM(COUNTIFS(G4:AK4,"C")) -> 0 | AO4: =SUM(COUNTIFS(G4:AK4,"G")) -> 27 | AP4: =SUM(COUNTIFS(G4:AK4,"W")) -> 4 | AQ4: =SUM(COUNTIFS(G5:AK5,"A"))+(COUNTIFS(G5:AK5,"B"))+(COUNTIFS(G5:AK5,"C"))+(COUNTIFS(G5:AK5,"G")) -> 0 | AR4: =SUM(COUNTIFS(G4:AK4,"PH")) -> 0 | AS4: =AL4+AM4+AN4+AO4+AR4+AP4+AQ4 -> 31
F5: E.D
A6: 2 | B6: 10976 | C6: KONGANI NARAYANA | D6: 10431 | E6: TECH SUPERVISOR | F6: Duty | G6: A | H6: A | I6: B | J6: B | K6: C | L6: C | M6: W | N6: A | O6: A | P6: B | Q6: B | R6: C | S6: C | T6: W | U6: A | V6: B | W6: B | X6: A | Y6: C | Z6: C | AA6: W | AB6: A | AC6: A | AD6: C | AE6: B | AF6: C | AG6: B | AH6: W | AI6: A | AJ6: A | AK6: B | AL6: =SUM(COUNTIFS(G6:AK6,"A")) -> 10 | AM6: =SUM(COUNTIFS(G6:AK6,"B")) -> 9 | AN6: =SUM(COUNTIFS(G6:AK6,"C")) -> 8 | AO6: =SUM(COUNTIFS(G6:AK6,"G")) -> 0 | AP6: =SUM(COUNTIFS(G6:AK6,"W")) -> 4 | AQ6: =SUM(COUNTIFS(G7:AK7,"A"))+(COUNTIFS(G7:AK7,"B"))+(COUNTIFS(G7:AK7,"C"))+(COUNTIFS(G7:AK7,"G")) -> 0 | AR6: =SUM(COUNTIFS(G6:AK6,"PH")) -> 0 | AS6: =AL6+AM6+AN6+AO6+AR6+AP6+AQ6 -> 31
F7: E.D
A8: 3 | B8: 10984 | C8: KUMMARA RAJYALAKSHMI | D8: 1227 | E8: TECH SUPERVISOR | F8: Duty | G8: G | H8: G | I8: G | J8: G | K8: W | L8: G | M8: G | N8: G | O8: G | P8: G | Q8: G | R8: W | S8: G | T8: G | U8: G | V8: G | W8: G | X8: G | Y8: W | Z8: G | AA8: G | AB8: G | AC8: G | AD8: G | AE8: G | AF8: W | AG8: G | AH8: G | AI8: G | AJ8: G | AK8: L | AL8: =SUM(COUNTIFS(G8:AK8,"A")) -> 0 | AM8: =SUM(COUNTIFS(G8:AK8,"B")) -> 0 | AN8: =SUM(COUNTIFS(G8:AK8,"C")) -> 0 | AO8: =SUM(COUNTIFS(G8:AK8,"G")) -> 26 | AP8: =SUM(COUNTIFS(G8:AK8,"W")) -> 4 | AQ8: =SUM(COUNTIFS(G9:AK9,"A"))+(COUNTIFS(G9:AK9,"B"))+(COUNTIFS(G9:AK9,"C"))+(COUNTIFS(G9:AK9,"G")) -> 0 | AR8: =SUM(COUNTIFS(G8:AK8,"PH")) -> 0 | AS8: =AL8+AM8+AN8+AO8+AR8+AP8+AQ8 -> 30
F9: E.D
A10: 4 | B10: 10986 | C10: KSHIROD KUMAR DAS | D10: 11038 | E10: TECH SUPERVISOR | F10: Duty | G10: G | H10: W | I10: G | J10: G | K10: G | L10: G | M10: L | N10: L | O10: L | P10: L | Q10: L | R10: L | S10: L | T10: L | U10: L | V10: L | W10: L | X10: L | Y10: L | Z10: L | AA10: L | AB10: L | AC10: G | AD10: G | AE10: G | AF10: G | AG10: G | AH10: G | AI10: G | AJ10: W | AK10: G | AL10: =SUM(COUNTIFS(G10:AK10,"A")) -> 0 | AM10: =SUM(COUNTIFS(G10:AK10,"B")) -> 0 | AN10: =SUM(COUNTIFS(G10:AK10,"C")) -> 0 | AO10: =SUM(COUNTIFS(G10:AK10,"G")) -> 13 | AP10: =SUM(COUNTIFS(G10:AK10,"W")) -> 2 | AQ10: =SUM(COUNTIFS(G11:AK11,"A"))+(COUNTIFS(G11:AK11,"B"))+(COUNTIFS(G11:AK11,"C"))+(COUNTIFS(G11:AK11,"G")) -> 0 | AR10: =SUM(COUNTIFS(G10:AK10,"PH")) -> 0 | AS10: =AL10+AM10+AN10+AO10+AR10+AP10+AQ10 -> 15
F11: E.D
A12: 5 | B12: 10013 | C12: HRUSIKESH PANDA | D12: 11182 | E12: TECH SUPERVISOR | F12: Duty | G12: W | H12: G | I12: A | J12: G | K12: B | L12: G | M12: A | N12: W | O12: G | P12: A | Q12: G | R12: B | S12: G | T12: A | U12: W | V12: A | W12: A | X12: G | Y12: A | Z12: G | AA12: A | AB12: W | AC12: B | AD12: B | AE12: B | AF12: A | AG12: A | AH12: A | AI12: W | AJ12: G | AK12: G | AL12: =SUM(COUNTIFS(G12:AK12,"A")) -> 11 | AM12: =SUM(COUNTIFS(G12:AK12,"B")) -> 5 | AN12: =SUM(COUNTIFS(G12:AK12,"C")) -> 0 | AO12: =SUM(COUNTIFS(G12:AK12,"G")) -> 10 | AP12: =SUM(COUNTIFS(G12:AK12,"W")) -> 5 | AQ12: =SUM(COUNTIFS(G13:AK13,"A"))+(COUNTIFS(G13:AK13,"B"))+(COUNTIFS(G13:AK13,"C"))+(COUNTIFS(G13:AK13,"G")) -> 0 | AR12: =SUM(COUNTIFS(G12:AK12,"PH")) -> 0 | AS12: =AL12+AM12+AN12+AO12+AR12+AP12+AQ12 -> 31
F13: E.D
A14: 6 | B14: 11365 | C14: BADAM SANDEEP | D14: 11203 | E14: TECH SUPERVISOR | F14: Duty | G14: C | H14: C | I14: W | J14: A | K14: A | L14: B | M14: C | N14: C | O14: C | P14: W | Q14: A | R14: A | S14: A | T14: C | U14: B | V14: A | W14: W | X14: C | Y14: B | Z14: B | AA14: C | AB14: C | AC14: B | AD14: W | AE14: C | AF14: B | AG14: B | AH14: C | AI14: C | AJ14: L | AK14: W | AL14: =SUM(COUNTIFS(G14:AK14,"A")) -> 6 | AM14: =SUM(COUNTIFS(G14:AK14,"B")) -> 7 | AN14: =SUM(COUNTIFS(G14:AK14,"C")) -> 12 | AO14: =SUM(COUNTIFS(G14:AK14,"G")) -> 0 | AP14: =SUM(COUNTIFS(G14:AK14,"W")) -> 5 | AQ14: =SUM(COUNTIFS(G15:AK15,"A"))+(COUNTIFS(G15:AK15,"B"))+(COUNTIFS(G15:AK15,"C"))+(COUNTIFS(G15:AK15,"G")) -> 0 | AR14: =SUM(COUNTIFS(G14:AK14,"PH")) -> 0 | AS14: =AL14+AM14+AN14+AO14+AR14+AP14+AQ14 -> 30
F15: E.D
A16: 7 | B16: 10989 | C16: B NAGENDRA BABU | D16: 10423 | E16: TECH SUPERVISOR | F16: Duty | G16: B | H16: B | I16: C | J16: C | K16: W | L16: A | M16: B | N16: B | O16: B | P16: C | Q16: C | R16: W | S16: B | T16: B | U16: C | V16: C | W16: C | X16: B | Y16: W | Z16: A | AA16: B | AB16: B | AC16: C | AD16: B | AE16: A | AF16: W | AG16: C | AH16: B | AI16: B | AJ16: B | AK16: C | AL16: =SUM(COUNTIFS(G16:AK16,"A")) -> 3 | AM16: =SUM(COUNTIFS(G16:AK16,"B")) -> 14 | AN16: =SUM(COUNTIFS(G16:AK16,"C")) -> 10 | AO16: =SUM(COUNTIFS(G16:AK16,"G")) -> 0 | AP16: =SUM(COUNTIFS(G16:AK16,"W")) -> 4 | AQ16: =SUM(COUNTIFS(G17:AK17,"A"))+(COUNTIFS(G17:AK17,"B"))+(COUNTIFS(G17:AK17,"C"))+(COUNTIFS(G17:AK17,"G")) -> 0 | AR16: =SUM(COUNTIFS(G16:AK16,"PH")) -> 0 | AS16: =AL16+AM16+AN16+AO16+AR16+AP16+AQ16 -> 31
F17: E.D
A18: 8 | B18: 10982 | C18: SAGAR KUMAR BEHERA | D18: 11101 | E18: TECH SUPERVISOR | F18: Duty | G18: A | H18: G | I18: G | J18: G | K18: G | L18: W | M18: G | N18: G | O18: G | P18: G | Q18: G | R18: G | S18: W | T18: G | U18: G | V18: G | W18: G | X18: G | Y18: G | Z18: W | AA18: G | AB18: G | AC18: G | AD18: A | AE18: G | AF18: B | AG18: W | AH18: A | AI18: A | AJ18: G | AK18: A | AL18: =SUM(COUNTIFS(G18:AK18,"A")) -> 5 | AM18: =SUM(COUNTIFS(G18:AK18,"B")) -> 1 | AN18: =SUM(COUNTIFS(G18:AK18,"C")) -> 0 | AO18: =SUM(COUNTIFS(G18:AK18,"G")) -> 21 | AP18: =SUM(COUNTIFS(G18:AK18,"W")) -> 4 | AQ18: =SUM(COUNTIFS(G19:AK19,"A"))+(COUNTIFS(G19:AK19,"B"))+(COUNTIFS(G19:AK19,"C"))+(COUNTIFS(G19:AK19,"G")) -> 0 | AR18: =SUM(COUNTIFS(G18:AK18,"PH")) -> 0 | AS18: =AL18+AM18+AN18+AO18+AR18+AP18+AQ18 -> 31
F19: E.D
A20: 9 | B20: 12076 | C20: JALEM ROHAN | D20: 11227 | E20: TECH SUPERVISOR | F20: Duty | G20: C | H20: C | I20: C | J20: W | K20: G | L20: B | M20: G | N20: G | O20: B | P20: G | Q20: W | R20: C | S20: C | T20: C | U20: C | V20: C | W20: B | X20: W | Y20: G | Z20: G | AA20: G | AB20: G | AC20: C | AD20: C | AE20: W | AF20: C | AG20: C | AH20: B | AI20: B | AJ20: B | AK20: C | AL20: =SUM(COUNTIFS(G20:AK20,"A")) -> 0 | AM20: =SUM(COUNTIFS(G20:AK20,"B")) -> 6 | AN20: =SUM(COUNTIFS(G20:AK20,"C")) -> 13 | AO20: =SUM(COUNTIFS(G20:AK20,"G")) -> 8 | AP20: =SUM(COUNTIFS(G20:AK20,"W")) -> 4 | AQ20: =SUM(COUNTIFS(G21:AK21,"A"))+(COUNTIFS(G21:AK21,"B"))+(COUNTIFS(G21:AK21,"C"))+(COUNTIFS(G21:AK21,"G")) -> 0 | AR20: =SUM(COUNTIFS(G20:AK20,"PH")) -> 0 | AS20: =AL20+AM20+AN20+AO20+AR20+AP20+AQ20 -> 31
F21: E.D
A22: 10 | B22: 11032 | C22: ANANDA SHA | D22: 11104 | E22: ELECTRICIAN | F22: Duty | G22: W | H22: C | I22: C | J22: B | K22: B | L22: A | M22: B | N22: W | O22: A | P22: A | Q22: G | R22: B | S22: B | T22: C | U22: W | V22: A | W22: A | X22: G | Y22: G | Z22: B | AA22: C | AB22: W | AC22: B | AD22: B | AE22: G | AF22: B | AG22: B | AH22: C | AI22: W | AJ22: B | AK22: B | AL22: =SUM(COUNTIFS(G22:AK22,"A")) -> 5 | AM22: =SUM(COUNTIFS(G22:AK22,"B")) -> 12 | AN22: =SUM(COUNTIFS(G22:AK22,"C")) -> 5 | AO22: =SUM(COUNTIFS(G22:AK22,"G")) -> 4 | AP22: =SUM(COUNTIFS(G22:AK22,"W")) -> 5 | AQ22: =SUM(COUNTIFS(G23:AK23,"A"))+(COUNTIFS(G23:AK23,"B"))+(COUNTIFS(G23:AK23,"C"))+(COUNTIFS(G23:AK23,"G")) -> 0 | AR22: =SUM(COUNTIFS(G22:AK22,"PH")) -> 0 | AS22: =AL22+AM22+AN22+AO22+AR22+AP22+AQ22 -> 31
F23: E.D
A24: 11 | B24: 10981 | C24: CHINTHAKUNTA GANESH | D24: 11053 | E24: ELECTRICIAN | F24: Duty | G24: C | H24: B | I24: L | J24: L | K24: W | L24: C | M24: C | N24: B | O24: G | P24: G | Q24: C | R24: W | S24: G | T24: A | U24: G | V24: G | W24: C | X24: C | Y24: W | Z24: A | AA24: G | AB24: G | AC24: G | AD24: C | AE24: C | AF24: W | AG24: A | AH24: B | AI24: G | AJ24: G | AK24: C | AL24: =SUM(COUNTIFS(G24:AK24,"A")) -> 3 | AM24: =SUM(COUNTIFS(G24:AK24,"B")) -> 3 | AN24: =SUM(COUNTIFS(G24:AK24,"C")) -> 9 | AO24: =SUM(COUNTIFS(G24:AK24,"G")) -> 10 | AP24: =SUM(COUNTIFS(G24:AK24,"W")) -> 4 | AQ24: =SUM(COUNTIFS(G25:AK25,"A"))+(COUNTIFS(G25:AK25,"B"))+(COUNTIFS(G25:AK25,"C"))+(COUNTIFS(G25:AK25,"G")) -> 0 | AR24: =SUM(COUNTIFS(G24:AK24,"PH")) -> 0 | AS24: =AL24+AM24+AN24+AO24+AR24+AP24+AQ24 -> 29
F25: E.D
A26: 12 | B26: 11651 | C26: RUDRA MADHAB SENAPATI | D26: 11194 | E26: ELECTRICIAN | F26: Duty | G26: L | H26: L | I26: L | J26: L | K26: L | L26: L | M26: L | N26: L | O26: L | P26: L | Q26: L | R26: L | S26: L | T26: L | U26: L | V26: L | W26: L | X26: L | Y26: L | Z26: L | AA26: L | AB26: L | AC26: L | AD26: L | AE26: L | AF26: L | AG26: L | AH26: L | AI26: L | AJ26: L | AK26: L | AL26: =SUM(COUNTIFS(G26:AK26,"A")) -> 0 | AM26: =SUM(COUNTIFS(G26:AK26,"B")) -> 0 | AN26: =SUM(COUNTIFS(G26:AK26,"C")) -> 0 | AO26: =SUM(COUNTIFS(G26:AK26,"G")) -> 0 | AP26: =SUM(COUNTIFS(G26:AK26,"W")) -> 0 | AQ26: =SUM(COUNTIFS(G27:AK27,"A"))+(COUNTIFS(G27:AK27,"B"))+(COUNTIFS(G27:AK27,"C"))+(COUNTIFS(G27:AK27,"G")) -> 0 | AR26: =SUM(COUNTIFS(G26:AK26,"PH")) -> 0 | AS26: =AL26+AM26+AN26+AO26+AR26+AP26+AQ26 -> 0
F27: E.D
A28: 13 | B28: 11377 | C28: MANOJ KUMAR DAS | D28: 11196 | E28: ELECTRICIAN | F28: Duty | G28: B | H28: A | I28: B | J28: C | K28: C | L28: B | M28: W | N28: A | O28: B | P28: B | Q28: B | R28: C | S28: C | T28: W | U28: B | V28: B | W28: B | X28: B | Y28: C | Z28: L | AA28: W | AB28: B | AC28: A | AD28: B | AE28: B | AF28: C | AG28: L | AH28: L | AI28: L | AJ28: L | AK28: L | AL28: =SUM(COUNTIFS(G28:AK28,"A")) -> 3 | AM28: =SUM(COUNTIFS(G28:AK28,"B")) -> 13 | AN28: =SUM(COUNTIFS(G28:AK28,"C")) -> 6 | AO28: =SUM(COUNTIFS(G28:AK28,"G")) -> 0 | AP28: =SUM(COUNTIFS(G28:AK28,"W")) -> 3 | AQ28: =SUM(COUNTIFS(G29:AK29,"A"))+(COUNTIFS(G29:AK29,"B"))+(COUNTIFS(G29:AK29,"C"))+(COUNTIFS(G29:AK29,"G")) -> 0 | AR28: =SUM(COUNTIFS(G28:AK28,"PH")) -> 0 | AS28: =AL28+AM28+AN28+AO28+AR28+AP28+AQ28 -> 25
F29: E.D
A30: 14 | B30: 1 | C30: BANAVATH BALAJI | D30: 11229 | E30: ELECTRICIAN | F30: Duty | G30: NEW JOINING | H30: G | I30: G | J30: G | K30: B | L30: A | M30: B | N30: G | O30: W | P30: C | Q30: B | R30: C | S30: C | T30: B | U30: C | V30: W | W30: L | X30: L | Y30: C | Z30: C | AA30: B | AB30: A | AC30: W | AD30: A | AE30: A | AF30: B | AG30: B | AH30: B | AI30: C | AJ30: W | AK30: G | AL30: =SUM(COUNTIFS(G30:AK30,"A")) -> 4 | AM30: =SUM(COUNTIFS(G30:AK30,"B")) -> 8 | AN30: =SUM(COUNTIFS(G30:AK30,"C")) -> 7 | AO30: =SUM(COUNTIFS(G30:AK30,"G")) -> 5 | AP30: =SUM(COUNTIFS(G30:AK30,"W")) -> 4 | AQ30: =SUM(COUNTIFS(G31:AK31,"A"))+(COUNTIFS(G31:AK31,"B"))+(COUNTIFS(G31:AK31,"C"))+(COUNTIFS(G31:AK31,"G")) -> 0 | AR30: =SUM(COUNTIFS(G30:AK30,"PH")) -> 0 | AS30: =AL30+AM30+AN30+AO30+AR30+AP30+AQ30 -> 28
F31: E.D
A32: 15 | B32: 2 | C32: GATTU BHANUTEJA | D32: 11230 | E32: ELECTRICIAN | F32: Duty | G32: NEW JOINING | H32: G | I32: G | J32: G | K32: C | L32: C | M32: C | N32: B | O32: W | P32: L | Q32: C | R32: B | S32: A | T32: A | U32: L | V32: W | W32: C | X32: L | Y32: A | Z32: A | AA32: A | AB32: A | AC32: C | AD32: C | AE32: A | AF32: A | AG32: A | AH32: A | AI32: B | AJ32: W | AK32: C | AL32: =SUM(COUNTIFS(G32:AK32,"A")) -> 10 | AM32: =SUM(COUNTIFS(G32:AK32,"B")) -> 3 | AN32: =SUM(COUNTIFS(G32:AK32,"C")) -> 8 | AO32: =SUM(COUNTIFS(G32:AK32,"G")) -> 3 | AP32: =SUM(COUNTIFS(G32:AK32,"W")) -> 3 | AQ32: =SUM(COUNTIFS(G33:AK33,"A"))+(COUNTIFS(G33:AK33,"B"))+(COUNTIFS(G33:AK33,"C"))+(COUNTIFS(G33:AK33,"G")) -> 0 | AR32: =SUM(COUNTIFS(G32:AK32,"PH")) -> 0 | AS32: =AL32+AM32+AN32+AO32+AR32+AP32+AQ32 -> 27
F33: E.D
A34: 16 | B34: 3 | C34: MERUPULA SANDEEP GOUD | D34: 11231 | E34: ELECTRICIAN | F34: Duty | G34: NEW JOINING | H34: G | I34: G | J34: A | K34: A | L34: B | M34: A | N34: C | O34: C | P34: B | Q34: A | R34: A | S34: A | T34: W | U34: A | V34: B | W34: B | X34: A | Y34: L | Z34: B | AA34: W | AB34: B | AC34: B | AD34: A | AE34: C | AF34: C | AG34: C | AH34: W | AI34: A | AJ34: A | AK34: A | AL34: =SUM(COUNTIFS(G34:AK34,"A")) -> 12 | AM34: =SUM(COUNTIFS(G34:AK34,"B")) -> 7 | AN34: =SUM(COUNTIFS(G34:AK34,"C")) -> 5 | AO34: =SUM(COUNTIFS(G34:AK34,"G")) -> 2 | AP34: =SUM(COUNTIFS(G34:AK34,"W")) -> 3 | AQ34: =SUM(COUNTIFS(G35:AK35,"A"))+(COUNTIFS(G35:AK35,"B"))+(COUNTIFS(G35:AK35,"C"))+(COUNTIFS(G35:AK35,"G")) -> 0 | AR34: =SUM(COUNTIFS(G34:AK34,"PH")) -> 0 | AS34: =AL34+AM34+AN34+AO34+AR34+AP34+AQ34 -> 29
F35: E.D
A36: 17 | B36: 4 | C36: RAJANIKANT | D36: 11232 | E36: ELECTRICIAN | F36: Duty | G36: NEW JOINING | J36: G | K36: G | L36: C | M36: B | N36: G | O36: W | P36: A | Q36: A | R36: B | S36: B | T36: L | U36: L | V36: L | W36: L | X36: L | Y36: L | Z36: L | AA36: L | AB36: L | AC36: L | AD36: L | AE36: L | AF36: L | AG36: L | AH36: L | AI36: L | AJ36: L | AK36: L | AL36: =SUM(COUNTIFS(G36:AK36,"A")) -> 2 | AM36: =SUM(COUNTIFS(G36:AK36,"B")) -> 3 | AN36: =SUM(COUNTIFS(G36:AK36,"C")) -> 1 | AO36: =SUM(COUNTIFS(G36:AK36,"G")) -> 3 | AP36: =SUM(COUNTIFS(G36:AK36,"W")) -> 1 | AQ36: =SUM(COUNTIFS(G37:AK37,"A"))+(COUNTIFS(G37:AK37,"B"))+(COUNTIFS(G37:AK37,"C"))+(COUNTIFS(G37:AK37,"G")) -> 0 | AR36: =SUM(COUNTIFS(G36:AK36,"PH")) -> 0 | AS36: =AL36+AM36+AN36+AO36+AR36+AP36+AQ36 -> 10
F37: E.D
A38: 18 | B38: 5 | C38: ALOKA MUDULI | D38: 11233 | E38: ELECTRICIAN | F38: Duty | G38: NEW JOINING | J38: G | K38: G | L38: G | M38: G | N38: C | O38: B | P38: A | Q38: G | R38: G | S38: B | T38: C | U38: C | V38: W | W38: G | X38: G | Y38: G | Z38: G | AA38: B | AB38: C | AC38: W | AD38: B | AE38: B | AF38: A | AG38: A | AH38: C | AI38: B | AJ38: W | AK38: B | AL38: =SUM(COUNTIFS(G38:AK38,"A")) -> 3 | AM38: =SUM(COUNTIFS(G38:AK38,"B")) -> 7 | AN38: =SUM(COUNTIFS(G38:AK38,"C")) -> 5 | AO38: =SUM(COUNTIFS(G38:AK38,"G")) -> 10 | AP38: =SUM(COUNTIFS(G38:AK38,"W")) -> 3 | AQ38: =SUM(COUNTIFS(G39:AK39,"A"))+(COUNTIFS(G39:AK39,"B"))+(COUNTIFS(G39:AK39,"C"))+(COUNTIFS(G39:AK39,"G")) -> 0 | AR38: =SUM(COUNTIFS(G38:AK38,"PH")) -> 0 | AS38: =AL38+AM38+AN38+AO38+AR38+AP38+AQ38 -> 28
F39: E.D
A40: 19 | B40: 6 | C40: MD Saleem | D40: 11237 | E40: ELECTRICIAN | F40: Duty | G40: NEW JOINING | M40: G | N40: G | O40: G | P40: G | Q40: A | R40: G | S40: G | T40: G | U40: A | V40: C | W40: W | X40: B | Y40: B | Z40: L | AA40: L | AB40: C | AC40: C | AD40: W | AE40: A | AF40: G | AG40: G | AH40: A | AI40: C | AJ40: C | AK40: W | AL40: =SUM(COUNTIFS(G40:AK40,"A")) -> 4 | AM40: =SUM(COUNTIFS(G40:AK40,"B")) -> 2 | AN40: =SUM(COUNTIFS(G40:AK40,"C")) -> 5 | AO40: =SUM(COUNTIFS(G40:AK40,"G")) -> 9 | AP40: =SUM(COUNTIFS(G40:AK40,"W")) -> 3 | AQ40: =SUM(COUNTIFS(G41:AK41,"A"))+(COUNTIFS(G41:AK41,"B"))+(COUNTIFS(G41:AK41,"C"))+(COUNTIFS(G41:AK41,"G")) -> 0 | AR40: =SUM(COUNTIFS(G40:AK40,"PH")) -> 0 | AS40: =AL40+AM40+AN40+AO40+AR40+AP40+AQ40 -> 23
...

Sheet PAYSHEET
AD2: grooming deduction
A3: MIDAS-B1&B2 FOR THE MONTH OF JUL-2026 | H3: ACTUAL COMPONENTS | Q3: EARNING COMPONENTS | AA3: DEDUCTIONS
A4: S.NO | B4: EMP CODE | C4: EMPLOYEE NAME | D4: Designation | E4: ACTUAL DAYS | F4: NET PAID DAYS | G4: EXTRA DEPLOYMENT | H4: GROSS SALARY | I4: BASIC | J4: DA | K4: HRA | L4: OTHER ALLOWANCE | M4: Bonus 8.33% (Basic + DA) | N4: Leave Wage (EL @ 18days) 4.93% | O4: Leave Wage (CL @ 12days) 3.29% | P4: National Holiday and Festival Holidays 10 days @2.88% | Q4: BASIC | R4: DA | S4: HRA | T4: OTHER ALLOWANCE | U4: Bonus 8.33% (Basic + DA) | V4: Leave Wage (EL @ 18days) 4.93% | W4: Leave Wage (CL @ 12days) 3.29% | X4: National Holiday and Festival Holidays 10 days @2.88% | Y4: Extra Deployment Amount | Z4: GROSS EARNINGS | AA4: EMPLOYEE PF@12% | AB4: EMPLOYEE ESI@0.75% | AC4: PROFESSION TAX | AD4: Advances | AE4: TOTAL DEDUCTIONS | AF4: NET PAY | AG4: EMPLOYER PF@13% | AH4: EMPLOYER ESI @3.25% / INSURANCE | AI4: CTC | AJ4: WO VALUE | AK4: WO EXCESS VALUE | AL4: CURRENT TAKE HOME
A5: 1 | B5: 11029 | C5: SUDHIR KUMAR RAUTARAY | D5: TECHNICAL EXECUTIVE | E5: 31 | F5: =VLOOKUP(B5,ATTENDANCE!$B$4:$AS$113,44,0) -> 31 | G5: 0 | H5: =I5+J5+K5+L5 -> 32704 | I5: 5557 | J5: 14443 | K5: =(I5+J5)*40% -> 8000 | L5: 4704 | M5: =(I5+J5)*8.33% -> 1666 | N5: =H5*4.93% -> 1612.3072 | O5: =H5*3.29% -> 1075.9616 | P5: =H5*2.88% -> 941.8752 | Q5: =I5/E5*F5 -> 5557 | R5: =J5/E5*F5 -> 14443 | S5: =+K5/E5*F5 -> 8000 | T5: =L5/E5*F5 -> 4704 | U5: =M5/E5*F5 -> 1666 | V5: =N5/E5*F5 -> 1612.3072 | W5: =O5/E5*F5 -> 1075.9616 | X5: =P5/E5*F5 -> 941.8752 | Y5: =(H5+M5+N5+O5+P5)/E5*G5 -> 0 | Z5: =Q5+R5+S5+T5+U5+V5+W5+X5+Y5 -> 38000.144 | AA5: =1800*F5/E5 -> 1800 | AB5: 0 | AC5: =IF(Z5>20000,200,IF(Z5>15000,150,0)) -> 200 | AD5: 0 | AE5: =AA5+AB5+AC5+AD5 -> 2000 | AF5: =ROUND(Z5-AE5,0) -> 36000 | AG5: =AA5*13/12 -> 1950 | AH5: 1000 | AI5: =Z5+AG5+AH5 -> 40950.144 | AJ5: =39780*(F5+G5)/E5 -> 39780 | AK5: =AJ5-AI5 -> -1170.144 | AL5: 36000
C6: TECHNICAL EXECUTIVE | E6: =SUM(E5) -> 31 | F6: =SUM(F5) -> 31 | G6: =SUM(G5) -> 0 | H6: =SUM(H5) -> 32704 | I6: =SUM(I5) -> 5557 | J6: =SUM(J5) -> 14443 | K6: =SUM(K5) -> 8000 | L6: =SUM(L5) -> 4704 | ... AL6: =SUM(AL5) -> 36000
A7: 2 | B7: 10984 | C7: K.RAJYALAKSHMI | D7: TECHNICAL SUPERVISOR | E7: 31 | F7: =VLOOKUP(B7,ATTENDANCE!$B$4:$AS$113,44,0) -> 30 | G7: 0 | H7: =I7+J7+K7+L7 -> 24715.5 | I7: 4722 | J7: 13778 | K7: 6215.5 | L7: 0 | M7: =(I7+J7)*8.33% -> 1541.05 | N7: =H7*4.93% -> 1218.4742 | O7: =H7*3.29% -> 813.13995 | P7: =H7*2.88% -> 711.8064 | Q7: =I7/E7*F7 -> 4569.6774 | R7: =J7/E7*F7 -> 13333.548 | S7: =+K7/E7*F7 -> 6015 | T7: =L7/E7*F7 -> 0 | U7: =M7/E7*F7 -> 1491.3387 | V7: =N7/E7*F7 -> 1179.1685 | W7: =O7/E7*F7 -> 786.90963 | X7: =P7/E7*F7 -> 688.8449 | Y7: =(H7+M7+N7+O7+P7)/E7*G7 -> 0 | Z7: =Q7+R7+S7+T7+U7+V7+W7+X7+Y7 -> 28064.488 | AA7: =1800*F7/E7 -> 1741.9355 | AB7: 0 | AC7: =IF(Z7>20000,200,IF(Z7>15000,150,0)) -> 200 | AD7: 0 | AE7: =AA7+AB7+AC7+AD7 -> 1941.9355 | AF7: =ROUND(Z7-AE7,0) -> 26123 | AG7: =AA7*13/12 -> 1887.0968 | AH7: 1000 | AI7: =Z7+AG7+AH7 -> 30951.584 | AJ7: =31244*(F7+G7)/E7 -> 30236.129 | AK7: =AJ7-AI7 -> -715.45532 | AL7: 27000
A8: =+A7+1 -> 3 | B8: 10986 | C8: KHIROD DAS | D8: TECHNICAL SUPERVISOR | E8: 31 | F8: =VLOOKUP(B8,ATTENDANCE!$B$4:$AS$113,44,0) -> 15 | G8: 0 | H8: =I8+J8+K8+L8 -> 26516 | I8: 4722 | J8: 13778 | K8: =(I8+J8)*40% -> 7400 | L8: 616 | M8: =(I8+J8)*8.33% -> 1541.05 | N8: =H8*4.93% -> 1307.2388 | O8: =H8*3.29% -> 872.3764 | P8: =H8*2.88% -> 763.6608 | Q8: =I8/E8*F8 -> 2284.8387 | R8: =J8/E8*F8 -> 6666.7742 | S8: =+K8/E8*F8 -> 3580.6452 | T8: =L8/E8*F8 -> 298.06452 | U8: =M8/E8*F8 -> 745.66935 | V8: =N8/E8*F8 -> 632.5349 | W8: =O8/E8*F8 -> 422.11761 | X8: =P8/E8*F8 -> 369.51329 | Y8: =(H8+M8+N8+O8+P8)/E8*G8 -> 0 | Z8: =Q8+R8+S8+T8+U8+V8+W8+X8+Y8 -> 15000.158 | AA8: =1800*F8/E8 -> 870.96774 | AB8: 0 | AC8: =IF(Z8>20000,200,IF(Z8>15000,150,0)) -> 150 | AD8: 0 | AE8: =AA8+AB8+AC8+AD8 -> 1020.9677 | AF8: =ROUND(Z8-AE8,0) -> 13979 | AG8: =AA8*13/12 -> 943.54839 | AH8: 1000 | AI8: =Z8+AG8+AH8 -> 16943.706 | AJ8: =31244*(F8+G8)/E8 -> 15118.065 | AK8: =AJ8-AI8 -> -1825.6416 | AL8: 29000
A9: =+A8+1 -> 4 | B9: 10976 | C9: KONGANI NARAYANA | D9: TECHNICAL SUPERVISOR | E9: 31 | F9: =VLOOKUP(B9,ATTENDANCE!$B$4:$AS$113,44,0) -> 31 | G9: 0 | H9: =I9+J9+K9+L9 -> 24715.5 | I9: 4722 | J9: 13778 | K9: 6215.5 | L9: 0 | M9: =(I9+J9)*8.33% -> 1541.05 | N9: =H9*4.93% -> 1218.4742 | O9: =H9*3.29% -> 813.13995 | P9: =H9*2.88% -> 711.8064 | Q9: =I9/E9*F9 -> 4722 | R9: =J9/E9*F9 -> 13778 | S9: =+K9/E9*F9 -> 6215.5 | T9: =L9/E9*F9 -> 0 | U9: =M9/E9*F9 -> 1541.05 | V9: =N9/E9*F9 -> 1218.4742 | W9: =O9/E9*F9 -> 813.13995 | X9: =P9/E9*F9 -> 711.8064 | Y9: =(H9+M9+N9+O9+P9)/E9*G9 -> 0 | Z9: =Q9+R9+S9+T9+U9+V9+W9+X9+Y9 -> 28999.97 | AA9: =1800*F9/E9 -> 1800 | AB9: 0 | AC9: =IF(Z9>20000,200,IF(Z9>15000,150,0)) -> 200 | AD9: 0 | AE9: =AA9+AB9+AC9+AD9 -> 2000 | AF9: =ROUND(Z9-AE9,0) -> 27000 | AG9: =AA9*13/12 -> 1950 | AH9: 1000 | AI9: =Z9+AG9+AH9 -> 31949.97 | AJ9: =31244*(F9+G9)/E9 -> 31244 | AK9: =AJ9-AI9 -> -705.9705 | AL9: 27000
A10: =+A9+1 -> 5 | B10: 11365 | C10: B.SANDEEP | D10: TECHNICAL SUPERVISOR | E10: 31 | F10: =VLOOKUP(B10,ATTENDANCE!$B$4:$AS$113,44,0) -> 30 | G10: 0 | H10: =I10+J10+K10+L10 -> 23815.4 | I10: 4722 | J10: 13778 | K10: 5315.4 | L10: 0 | M10: =(I10+J10)*8.33% -> 1541.05 | N10: =H10*4.93% -> 1174.0992 | O10: =H10*3.29% -> 783.52666 | P10: =H10*2.88% -> 685.88352 | Q10: =I10/E10*F10 -> 4569.6774 | R10: =J10/E10*F10 -> 13333.548 | S10: =+K10/E10*F10 -> 5143.9355 | T10: =L10/E10*F10 -> 0 | U10: =M10/E10*F10 -> 1491.3387 | V10: =N10/E10*F10 -> 1136.2251 | W10: =O10/E10*F10 -> 758.25161 | X10: =P10/E10*F10 -> 663.75825 | Y10: =(H10+M10+N10+O10+P10)/E10*G10 -> 0 | Z10: =Q10+R10+S10+T10+U10+V10+W10+X10+Y10 -> 27096.735 | AA10: =1800*F10/E10 -> 1741.9355 | AB10: 0 | AC10: =IF(Z10>20000,200,IF(Z10>15000,150,0)) -> 200 | AD10: 0 | AE10: =AA10+AB10+AC10+AD10 -> 1941.9355 | AF10: =ROUND(Z10-AE10,0) -> 25155 | AG10: =AA10*13/12 -> 1887.0968 | AH10: 1000 | AI10: =Z10+AG10+AH10 -> 29983.832 | AJ10: =31244*(F10+G10)/E10 -> 30236.129 | AK10: =AJ10-AI10 -> 252.29735 | AL10: 26000
A11: =+A10+1 -> 6 | B11: 10989 | C11: NAGENDRA BABU | D11: TECHNICAL SUPERVISOR | E11: 31 | F11: =VLOOKUP(B11,ATTENDANCE!$B$4:$AS$113,44,0) -> 31 | G11: 0 | H11: =I11+J11+K11+L11 -> 24715.4 | I11: 4722 | J11: 13778 | K11: 6215.4 | L11: 0 | M11: =(I11+J11)*8.33% -> 1541.05 | N11: =H11*4.93% -> 1218.4692 | O11: =H11*3.29% -> 813.13666 | P11: =H11*2.88% -> 711.80352 | Q11: =I11/E11*F11 -> 4722 | R11: =J11/E11*F11 -> 13778 | S11: =+K11/E11*F11 -> 6215.4 | T11: =L11/E11*F11 -> 0 | U11: =M11/E11*F11 -> 1541.05 | V11: =N11/E11*F11 -> 1218.4692 | W11: =O11/E11*F11 -> 813.13666 | X11: =P11/E11*F11 -> 711.80352 | Y11: =(H11+M11+N11+O11+P11)/E11*G11 -> 0 | Z11: =Q11+R11+S11+T11+U11+V11+W11+X11+Y11 -> 28999.859 | AA11: =1800*F11/E11 -> 1800 | AB11: 0 | AC11: =IF(Z11>20000,200,IF(Z11>15000,150,0)) -> 200 | AD11: 0 | AE11: =AA11+AB11+AC11+AD11 -> 2000 | AF11: =ROUND(Z11-AE11,0) -> 27000 | AG11: =AA11*13/12 -> 1950 | AH11: 1000 | AI11: =Z11+AG11+AH11 -> 31949.859 | AJ11: =31244*(F11+G11)/E11 -> 31244 | AK11: =AJ11-AI11 -> -705.8594 | AL11: 27000
A12: =+A11+1 -> 7 | B12: 10982 | C12: SAGAR KUMAR BEHERA | D12: TECHNICAL SUPERVISOR | E12: 31 | F12: =VLOOKUP(B12,ATTENDANCE!$B$4:$AS$113,44,0) -> 31 | G12: 0 | H12: =I12+J12+K12+L12 -> 23365 | I12: 4722 | J12: 13778 | K12: 4865 | L12: 0 | M12: =(I12+J12)*8.33% -> 1541.05 | N12: =H12*4.93% -> 1151.8945 | O12: =H12*3.29% -> 768.7085 | P12: =H12*2.88% -> 672.912 | Q12: =I12/E12*F12 -> 4722 | R12: =J12/E12*F12 -> 13778 | S12: =+K12/E12*F12 -> 4865 | T12: =L12/E12*F12 -> 0 | U12: =M12/E12*F12 -> 1541.05 | V12: =N12/E12*F12 -> 1151.8945 | W12: =O12/E12*F12 -> 768.7085 | X12: =P12/E12*F12 -> 672.912 | Y12: =(H12+M12+N12+O12+P12)/E12*G12 -> 0 | Z12: =Q12+R12+S12+T12+U12+V12+W12+X12+Y12 -> 27499.565 | AA12: =1800*F12/E12 -> 1800 | AB12: 0 | AC12: =IF(Z12>20000,200,IF(Z12>15000,150,0)) -> 200 | AD12: 0 | AE12: =AA12+AB12+AC12+AD12 -> 2000 | AF12: =ROUND(Z12-AE12,0) -> 25500 | AG12: =AA12*13/12 -> 1950 | AH12: 1000 | AI12: =Z12+AG12+AH12 -> 30449.565 | AJ12: =31244*(F12+G12)/E12 -> 31244 | AK12: =AJ12-AI12 -> 794.435 | AL12: 25500
A13: =+A12+1 -> 8 | B13: 12076 | C13: JALEM ROHAN | D13: TECHNICAL SUPERVISOR | E13: 31 | F13: =VLOOKUP(B13,ATTENDANCE!$B$4:$AS$113,44,0) -> 31 | G13: 0 | H13: =I13+J13+K13+L13 -> 22915 | I13: 4722 | J13: 13778 | K13: 4415 | L13: 0 | M13: =(I13+J13)*8.33% -> 1541.05 | N13: =H13*4.93% -> 1129.7095 | O13: =H13*3.29% -> 753.9035 | P13: =H13*2.88% -> 659.952 | Q13: =I13/E13*F13 -> 4722 | R13: =J13/E13*F13 -> 13778 | S13: =+K13/E13*F13 -> 4415 | T13: =L13/E13*F13 -> 0 | U13: =M13/E13*F13 -> 1541.05 | V13: =N13/E13*F13 -> 1129.7095 | W13: =O13/E13*F13 -> 753.9035 | X13: =P13/E13*F13 -> 659.952 | Y13: =(H13+M13+N13+O13+P13)/E13*G13 -> 0 | Z13: =Q13+R13+S13+T13+U13+V13+W13+X13+Y13 -> 26999.615 | AA13: =1800*F13/E13 -> 1800 | AB13: 0 | AC13: =IF(Z13>20000,200,IF(Z13>15000,150,0)) -> 200 | AD13: 0 | AE13: =AA13+AB13+AC13+AD13 -> 2000 | AF13: =ROUND(Z13-AE13,0) -> 25000 | AG13: =AA13*13/12 -> 1950 | AH13: 1000 | AI13: =Z13+AG13+AH13 -> 29949.615 | AJ13: =31244*(F13+G13)/E13 -> 31244 | AK13: =AJ13-AI13 -> 1294.385 | AL13: 25000
A14: =+A13+1 -> 9 | B14: 10013 | C14: H.PANDA | D14: TECHNICAL SUPERVISOR | E14: 31 | F14: =VLOOKUP(B14,ATTENDANCE!$B$4:$AS$113,44,0) -> 31 | G14: 0 | H14: =I14+J14+K14+L14 -> 23815.4 | I14: 4722 | J14: 13778 | K14: 5315.4 | L14: 0 | M14: =(I14+J14)*8.33% -> 1541.05 | N14: =H14*4.93% -> 1174.0992 | O14: =H14*3.29% -> 783.52666 | P14: =H14*2.88% -> 685.88352 | Q14: =I14/E14*F14 -> 4722 | R14: =J14/E14*F14 -> 13778 | S14: =+K14/E14*F14 -> 5315.4 | T14: =L14/E14*F14 -> 0 | U14: =M14/E14*F14 -> 1541.05 | V14: =N14/E14*F14 -> 1174.0992 | W14: =O14/E14*F14 -> 783.52666 | X14: =P14/E14*F14 -> 685.88352 | Y14: =(H14+M14+N14+O14+P14)/E14*G14 -> 0 | Z14: =Q14+R14+S14+T14+U14+V14+W14+X14+Y14 -> 27999.959 | AA14: =1800*F14/E14 -> 1800 | AB14: 0 | AC14: =IF(Z14>20000,200,IF(Z14>15000,150,0)) -> 200 | AD14: 0 | AE14: =AA14+AB14+AC14+AD14 -> 2000 | AF14: =ROUND(Z14-AE14,0) -> 26000 | AG14: =AA14*13/12 -> 1950 | AH14: 1000 | AI14: =Z14+AG14+AH14 -> 30949.959 | AJ14: =31244*(F14+G14)/E14 -> 31244 | AK14: =AJ14-AI14 -> 294.0406 | AL14: 26000
C15: TECHNICAL SUPERVISOR | E15: =SUM(E7:E14) -> 248 | F15: =SUM(F7:F14) -> 230 | G15: =SUM(G7:G14) -> 0 | H15: =SUM(H7:H14) -> 194573.2 | I15: =SUM(I7:I14) -> 37776 | J15: =SUM(J7:J14) -> 110224 | K15: =SUM(K7:K14) -> 45957.2 | L15: =SUM(L7:L14) -> 616 | ... AL15: =SUM(AL7:AL14) -> 212500
A16: =A14+1 -> 10 | B16: 11032 | C16: ANANDA SHA | D16: ELECTRICIAN | E16: 31 | F16: =VLOOKUP(B16,ATTENDANCE!$B$4:$AS$113,44,0) -> 31 | G16: 0 | H16: =I16+J16+K16+L16 -> 20935 | I16: 4722 | J16: 13778 | K16: 2435 | L16: 0 | M16: =(I16+J16)*8.33% -> 1541.05 | N16: =H16*4.93% -> 1032.0955 | O16: =H16*3.29% -> 688.7615 | P16: =H16*2.88% -> 602.928 | Q16: =I16/E16*F16 -> 4722 | R16: =J16/E16*F16 -> 13778 | S16: =+K16/E16*F16 -> 2435 | T16: =L16/E16*F16 -> 0 | U16: =M16/E16*F16 -> 1541.05 | V16: =N16/E16*F16 -> 1032.0955 | W16: =O16/E16*F16 -> 688.7615 | X16: =P16/E16*F16 -> 602.928 | Y16: =(H16+M16+N16+O16+P16)/E16*G16 -> 0 | Z16: =Q16+R16+S16+T16+U16+V16+W16+X16+Y16 -> 24799.835 | AA16: =1800*F16/E16 -> 1800 | AB16: 0 | AC16: =IF(Z16>20000,200,IF(Z16>15000,150,0)) -> 200 | AD16: 0 | AE16: =AA16+AB16+AC16+AD16 -> 2000 | AF16: =ROUND(Z16-AE16,0) -> 22800 | AG16: =AA16*13/12 -> 1950 | AH16: 1000 | AI16: =Z16+AG16+AH16 -> 27749.835 | AJ16: =26607*(F16+G16)/E16 -> 26607 | AK16: =AJ16-AI16 -> -1142.835 | AL16: 22800
A17: =A16+1 -> 11 | B17: 10981 | C17: C. GANESH | D17: ELECTRICIAN | E17: 31 | F17: =VLOOKUP(B17,ATTENDANCE!$B$4:$AS$113,44,0) -> 29 | G17: 0 | H17: =I17+J17+K17+L17 -> 20215 | I17: 4722 | J17: 13778 | K17: 1715 | L17: 0 | M17: =(I17+J17)*8.33% -> 1541.05 | N17: =H17*4.93% -> 996.5995 | O17: =H17*3.29% -> 665.0735 | P17: =H17*2.88% -> 582.192 | Q17: =I17/E17*F17 -> 4417.3548 | R17: =J17/E17*F17 -> 12889.097 | S17: =+K17/E17*F17 -> 1604.3548 | T17: =L17/E17*F17 -> 0 | U17: =M17/E17*F17 -> 1441.6274 | V17: =N17/E17*F17 -> 932.30276 | W17: =O17/E17*F17 -> 622.16553 | X17: =P17/E17*F17 -> 544.63123 | Y17: =(H17+M17+N17+O17+P17)/E17*G17 -> 0 | Z17: =Q17+R17+S17+T17+U17+V17+W17+X17+Y17 -> 22451.533 | AA17: =1800*F17/E17 -> 1683.871 | AB17: 0 | AC17: =IF(Z17>20000,200,IF(Z17>15000,150,0)) -> 200 | AD17: 0 | AE17: =AA17+AB17+AC17+AD17 -> 1883.871 | AF17: =ROUND(Z17-AE17,0) -> 20568 | AG17: =AA17*13/12 -> 1824.1935 | AH17: 1000 | AI17: =Z17+AG17+AH17 -> 25275.727 | AJ17: =26607*(F17+G17)/E17 -> 24890.419 | AK17: =AJ17-AI17 -> -385.30758 | AL17: 22000
A18: =A17+1 -> 12 | B18: 11377 | C18: MANOJ KUMAR | D18: ELECTRICIAN | E18: 31 | F18: =VLOOKUP(B18,ATTENDANCE!$B$4:$AS$113,44,0) -> 25 | G18: 0 | H18: =I18+J18+K18+L18 -> 20215 | I18: 4722 | J18: 13778 | K18: 1715 | L18: 0 | M18: =(I18+J18)*8.33% -> 1541.05 | N18: =H18*4.93% -> 996.5995 | O18: =H18*3.29% -> 665.0735 | P18: =H18*2.88% -> 582.192 | Q18: =I18/E18*F18 -> 3808.0645 | R18: =J18/E18*F18 -> 11111.29 | S18: =+K18/E18*F18 -> 1383.0645 | T18: =L18/E18*F18 -> 0 | U18: =M18/E18*F18 -> 1242.7823 | V18: =N18/E18*F18 -> 803.70927 | W18: =O18/E18*F18 -> 536.3496 | X18: =P18/E18*F18 -> 469.50968 | Y18: =(H18+M18+N18+O18+P18)/E18*G18 -> 0 | Z18: =Q18+R18+S18+T18+U18+V18+W18+X18+Y18 -> 19354.77 | AA18: =1800*F18/E18 -> 1451.6129 | AB18: 0 | AC18: =IF(Z18>20000,200,IF(Z18>15000,150,0)) -> 150 | AD18: 0 | AE18: =AA18+AB18+AC18+AD18 -> 1601.6129 | AF18: =ROUND(Z18-AE18,0) -> 17753 | AG18: =AA18*13/12 -> 1572.5806 | AH18: 1000 | AI18: =Z18+AG18+AH18 -> 21927.351 | AJ18: =26607*(F18+G18)/E18 -> 21457.258 | AK18: =AJ18-AI18 -> -470.09274 | AL18: 22000
A19: =A18+1 -> 13 | B19: 1 | C19: BANAVATH BALAJI | D19: ELECTRICIAN | E19: 31 | F19: =VLOOKUP(B19,ATTENDANCE!$B$4:$AS$113,44,0) -> 28 | G19: 0 | H19: =I19+J19+K19+L19 -> 17716 | I19: 4722 | J19: 12994 | K19: 0 | L19: 0 | M19: =(I19+J19)*8.33% -> 1475.7428 | N19: =H19*4.93% -> 873.3988 | O19: =H19*3.29% -> 582.8564 | P19: =H19*2.88% -> 510.2208 | Q19: =I19/E19*F19 -> 4265.0323 | R19: =J19/E19*F19 -> 11736.516 | S19: =+K19/E19*F19 -> 0 | T19: =L19/E19*F19 -> 0 | U19: =M19/E19*F19 -> 1332.929 | V19: =N19/E19*F19 -> 788.87634 | W19: =O19/E19*F19 -> 526.45094 | X19: =P19/E19*F19 -> 460.84459 | Y19: =(H19+M19+N19+O19+P19)/E19*G19 -> 0 | Z19: =Q19+R19+S19+T19+U19+V19+W19+X19+Y19 -> 19110.649 | AA19: =1800*F19/E19 -> 1625.8065 | AB19: =Z19*0.75% -> 143.32987 | AC19: =IF(Z19>20000,200,IF(Z19>15000,150,0)) -> 150 | AD19: 0 | AE19: =AA19+AB19+AC19+AD19 -> 1919.1363 | AF19: =ROUND(Z19-AE19,0) -> 17192 | AG19: =AA19*13/12 -> 1761.2903 | AH19: =AB19*3.25/0.75 -> 621.0961 | AI19: =Z19+AG19+AH19 -> 21493.036 | AJ19: =26607*(F19+G19)/E19 -> 24032.129 | AK19: =AJ19-AI19 -> 2539.0934 | AL19: 22000
A20: =A19+1 -> 14 | B20: 2 | C20: GATTU BHANUTEJA | D20: ELECTRICIAN | E20: 31 | F20: =VLOOKUP(B20,ATTENDANCE!$B$4:$AS$113,44,0) -> 27 | G20: 0 | H20: =I20+J20+K20+L20 -> 17716 | I20: 4722 | J20: 12994 | K20: 0 | L20: 0 | M20: =(I20+J20)*8.33% -> 1475.7428 | N20: =H20*4.93% -> 873.3988 | O20: =H20*3.29% -> 582.8564 | P20: =H20*2.88% -> 510.2208 | Q20: =I20/E20*F20 -> 4112.7097 | R20: =J20/E20*F20 -> 11317.355 | S20: =+K20/E20*F20 -> 0 | T20: =L20/E20*F20 -> 0 | U20: =M20/E20*F20 -> 1285.3244 | V20: =N20/E20*F20 -> 760.70218 | W20: =O20/E20*F20 -> 507.64912 | X20: =P20/E20*F20 -> 444.38586 | Y20: =(H20+M20+N20+O20+P20)/E20*G20 -> 0 | Z20: =Q20+R20+S20+T20+U20+V20+W20+X20+Y20 -> 18428.126 | AA20: =1800*F20/E20 -> 1567.7419 | AB20: =Z20*0.75% -> 138.21095 | AC20: =IF(Z20>20000,200,IF(Z20>15000,150,0)) -> 150 | AD20: 0 | AE20: =AA20+AB20+AC20+AD20 -> 1855.9529 | AF20: =ROUND(Z20-AE20,0) -> 16572 | AG20: =AA20*13/12 -> 1698.3871 | AH20: =AB20*3.25/0.75 -> 598.9141 | AI20: =Z20+AG20+AH20 -> 20725.427 | AJ20: =26607*(F20+G20)/E20 -> 23173.839 | AK20: =AJ20-AI20 -> 2448.4115 | AL20: 22000
A21: =A20+1 -> 15 | B21: 3 | C21: MERUPULA SANDEEP GOUD | D21: ELECTRICIAN | E21: 31 | F21: =VLOOKUP(B21,ATTENDANCE!$B$4:$AS$113,44,0) -> 29 | G21: 0 | H21: =I21+J21+K21+L21 -> 17716 | I21: 4722 | J21: 12994 | K21: 0 | L21: 0 | M21: =(I21+J21)*8.33% -> 1475.7428 | N21: =H21*4.93% -> 873.3988 | O21: =H21*3.29% -> 582.8564 | P21: =H21*2.88% -> 510.2208 | Q21: =I21/E21*F21 -> 4417.3548 | R21: =J21/E21*F21 -> 12155.677 | S21: =+K21/E21*F21 -> 0 | T21: =L21/E21*F21 -> 0 | U21: =M21/E21*F21 -> 1380.5336 | V21: =N21/E21*F21 -> 817.05049 | W21: =O21/E21*F21 -> 545.25276 | X21: =P21/E21*F21 -> 477.30333 | Y21: =(H21+M21+N21+O21+P21)/E21*G21 -> 0 | Z21: =Q21+R21+S21+T21+U21+V21+W21+X21+Y21 -> 19793.172 | AA21: =1800*F21/E21 -> 1683.871 | AB21: =Z21*0.75% -> 148.44879 | AC21: =IF(Z21>20000,200,IF(Z21>15000,150,0)) -> 150 | AD21: 0 | AE21: =AA21+AB21+AC21+AD21 -> 1982.3198 | AF21: =ROUND(Z21-AE21,0) -> 17811 | AG21: =AA21*13/12 -> 1824.1935 | AH21: =AB21*3.25/0.75 -> 643.2781 | AI21: =Z21+AG21+AH21 -> 22260.644 | AJ21: =26607*(F21+G21)/E21 -> 24890.419 | AK21: =AJ21-AI21 -> 2629.7753 | AL21: 22000
A22: =A21+1 -> 16 | B22: 4 | C22: RAJANIKANT | D22: ELECTRICIAN | E22: 31 | F22: =VLOOKUP(B22,ATTENDANCE!$B$4:$AS$113,44,0) -> 10 | G22: 0 | H22: =I22+J22+K22+L22 -> 17716 | I22: 4722 | J22: 12994 | K22: 0 | L22: 0 | M22: =(I22+J22)*8.33% -> 1475.7428 | N22: =H22*4.93% -> 873.3988 | O22: =H22*3.29% -> 582.8564 | P22: =H22*2.88% -> 510.2208 | Q22: =I22/E22*F22 -> 1523.2258 | R22: =J22/E22*F22 -> 4191.6129 | S22: =+K22/E22*F22 -> 0 | T22: =L22/E22*F22 -> 0 | U22: =M22/E22*F22 -> 476.04606 | V22: =N22/E22*F22 -> 281.74155 | W22: =O22/E22*F22 -> 188.01819 | X22: =P22/E22*F22 -> 164.58735 | Y22: =(H22+M22+N22+O22+P22)/E22*G22 -> 0 | Z22: =Q22+R22+S22+T22+U22+V22+W22+X22+Y22 -> 6825.2319 | AA22: =1800*F22/E22 -> 580.64516 | AB22: =Z22*0.75% -> 51.189239 | AC22: =IF(Z22>20000,200,IF(Z22>15000,150,0)) -> 0 | AD22: 0 | AE22: =AA22+AB22+AC22+AD22 -> 631.8344 | AF22: =ROUND(Z22-AE22,0) -> 6193 | AG22: =AA22*13/12 -> 629.03226 | AH22: =AB22*3.25/0.75 -> 221.82004 | AI22: =Z22+AG22+AH22 -> 7676.0842 | AJ22: =26607*(F22+G22)/E22 -> 8582.9032 | AK22: =AJ22-AI22 -> 906.81906 | AL22: 22000
A23: =A22+1 -> 17 | B23: 5 | C23: ALOKA MUDULI | D23: ELECTRICIAN | E23: 31 | F23: =VLOOKUP(B23,ATTENDANCE!$B$4:$AS$113,44,0) -> 28 | G23: 0 | H23: =I23+J23+K23+L23 -> 18421 | I23: 4722 | J23: 13699 | K23: 0 | L23: 0 | M23: =(I23+J23)*8.33% -> 1534.4693 | N23: =H23*4.93% -> 908.1553 | O23: =H23*3.29% -> 606.0509 | P23: =H23*2.88% -> 530.5248 | Q23: =I23/E23*F23 -> 4265.0323 | R23: =J23/E23*F23 -> 12373.29 | S23: =+K23/E23*F23 -> 0 | T23: =L23/E23*F23 -> 0 | U23: =M23/E23*F23 -> 1385.9723 | V23: =N23/E23*F23 -> 820.2693 | W23: =O23/E23*F23 -> 547.40081 | X23: =P23/E23*F23 -> 479.18369 | Y23: =(H23+M23+N23+O23+P23)/E23*G23 -> 0 | Z23: =Q23+R23+S23+T23+U23+V23+W23+X23+Y23 -> 19871.149 | AA23: =1800*F23/E23 -> 1625.8065 | AB23: 0 | AC23: =IF(Z23>20000,200,IF(Z23>15000,150,0)) -> 150 | AD23: 0 | AE23: =AA23+AB23+AC23+AD23 -> 1775.8065 | AF23: =ROUND(Z23-AE23,0) -> 18095 | AG23: =AA23*13/12 -> 1761.2903 | AH23: 1000 | AI23: =Z23+AG23+AH23 -> 22632.439 | AJ23: =26607*(F23+G23)/E23 -> 24032.129 | AK23: =AJ23-AI23 -> 1399.6901 | AL23: 22000
A24: =A23+1 -> 18 | B24: 6 | C24: MD Saleem | D24: ELECTRICIAN | E24: 31 | F24: =VLOOKUP(B24,ATTENDANCE!$B$4:$AS$113,44,0) -> 23 | G24: 0 | H24: =I24+J24+K24+L24 -> 17716 | I24: 4722 | J24: 12994 | K24: 0 | L24: 0 | M24: =(I24+J24)*8.33% -> 1475.7428 | N24: =H24*4.93% -> 873.3988 | O24: =H24*3.29% -> 582.8564 | P24: =H24*2.88% -> 510.2208 | Q24: =I24/E24*F24 -> 3503.4194 | R24: =J24/E24*F24 -> 9640.7097 | S24: =+K24/E24*F24 -> 0 | T24: =L24/E24*F24 -> 0 | U24: =M24/E24*F24 -> 1094.9059 | V24: =N24/E24*F24 -> 648.00556 | W24: =O24/E24*F24 -> 432.44185 | X24: =P24/E24*F24 -> 378.55092 | Y24: =(H24+M24+N24+O24+P24)/E24*G24 -> 0 | Z24: =Q24+R24+S24+T24+U24+V24+W24+X24+Y24 -> 15698.033 | AA24: =1800*F24/E24 -> 1335.4839 | AB24: =Z24*0.75% -> 117.73525 | AC24: =IF(Z24>20000,200,IF(Z24>15000,150,0)) -> 150 | AD24: 0 | AE24: =AA24+AB24+AC24+AD24 -> 1603.2191 | AF24: =ROUND(Z24-AE24,0) -> 14095 | AG24: =AA24*13/12 -> 1446.7742 | AH24: =AB24*3.25/0.75 -> 510.18608 | AI24: =Z24+AG24+AH24 -> 17654.994 | AJ24: =26607*(F24+G24)/E24 -> 19740.677 | AK24: =AJ24-AI24 -> 2085.6838 | AL24: 22000
A25: =A24+1 -> 19 | B25: 7 | C25: Shaik Shaheed | D25: ELECTRICIAN | E25: 31 | F25: =VLOOKUP(B25,ATTENDANCE!$B$4:$AS$113,44,0) -> 24 | G25: 0 | H25: =I25+J25+K25+L25 -> 17716 | I25: 4722 | J25: 12994 | K25: 0 | L25: 0 | M25: =(I25+J25)*8.33% -> 1475.7428 | N25: =H25*4.93% -> 873.3988 | O25: =H25*3.29% -> 582.8564 | P25: =H25*2.88% -> 510.2208 | Q25: =I25/E25*F25 -> 3655.7419 | R25: =J25/E25*F25 -> 10059.871 | S25: =+K25/E25*F25 -> 0 | T25: =L25/E25*F25 -> 0 | U25: =M25/E25*F25 -> 1142.5106 | V25: =N25/E25*F25 -> 676.17972 | W25: =O25/E25*F25 -> 451.24366 | X25: =P25/E25*F25 -> 395.00965 | Y25: =(H25+M25+N25+O25+P25)/E25*G25 -> 0 | Z25: =Q25+R25+S25+T25+U25+V25+W25+X25+Y25 -> 16380.556 | AA25: =1800*F25/E25 -> 1393.5484 | AB25: =Z25*0.75% -> 122.85417 | AC25: =IF(Z25>20000,200,IF(Z25>15000,150,0)) -> 150 | AD25: 0 | AE25: =AA25+AB25+AC25+AD25 -> 1666.4026 | AF25: =ROUND(Z25-AE25,0) -> 14714 | AG25: =AA25*13/12 -> 1509.6774 | AH25: =AB25*3.25/0.75 -> 532.36809 | AI25: =Z25+AG25+AH25 -> 18422.602 | AJ25: =26607*(F25+G25)/E25 -> 20598.968 | AK25: =AJ25-AI25 -> 2176.3657 | AL25: 22000
A26: =A25+1 -> 20 | B26: 8 | C26: KAZIPETA RAVI KIRAN | D26: ELECTRICIAN | E26: 31 | F26: =VLOOKUP(B26,ATTENDANCE!$B$4:$AS$113,44,0) -> 10 | G26: 0 | H26: =I26+J26+K26+L26 -> 17716 | I26: 4722 | J26: 12994 | K26: 0 | L26: 0 | M26: =(I26+J26)*8.33% -> 1475.7428 | N26: =H26*4.93% -> 873.3988 | O26: =H26*3.29% -> 582.8564 | P26: =H26*2.88% -> 510.2208 | Q26: =I26/E26*F26 -> 1523.2258 | R26: =J26/E26*F26 -> 4191.6129 | S26: =+K26/E26*F26 -> 0 | T26: =L26/E26*F26 -> 0 | U26: =M26/E26*F26 -> 476.04606 | V26: =N26/E26*F26 -> 281.74155 | W26: =O26/E26*F26 -> 188.01819 | X26: =P26/E26*F26 -> 164.58735 | Y26: =(H26+M26+N26+O26+P26)/E26*G26 -> 0 | Z26: =Q26+R26+S26+T26+U26+V26+W26+X26+Y26 -> 6825.2319 | AA26: =1800*F26/E26 -> 580.64516 | AB26: =Z26*0.75% -> 51.189239 | AC26: =IF(Z26>20000,200,IF(Z26>15000,150,0)) -> 0 | AD26: 0 | AE26: =AA26+AB26+AC26+AD26 -> 631.8344 | AF26: =ROUND(Z26-AE26,0) -> 6193 | AG26: =AA26*13/12 -> 629.03226 | AH26: =AB26*3.25/0.75 -> 221.82004 | AI26: =Z26+AG26+AH26 -> 7676.0842 | AJ26: =26607*(F26+G26)/E26 -> 8582.9032 | AK26: =AJ26-AI26 -> 906.81906 | AL26: 22000
A27: =A26+1 -> 21 | B27: 11958 | C27: M.PRATHAP KUMAR | D27: ELECTRICIAN | E27: 31 | F27: =VLOOKUP(B27,ATTENDANCE!$B$4:$AS$113,44,0) -> 6 | G27: 0 | H27: =I27+J27+K27+L27 -> 20215 | I27: 4722 | J27: 13778 | K27: 1715 | L27: 0 | M27: =(I27+J27)*8.33% -> 1541.05 | N27: =H27*4.93% -> 996.5995 | O27: =H27*3.29% -> 665.0735 | P27: =H27*2.88% -> 582.192 | Q27: =I27/E27*F27 -> 913.93548 | R27: =J27/E27*F27 -> 2666.7097 | S27: =+K27/E27*F27 -> 331.93548 | T27: =L27/E27*F27 -> 0 | U27: =M27/E27*F27 -> 298.26774 | V27: =N27/E27*F27 -> 192.89023 | W27: =O27/E27*F27 -> 128.7239 | X27: =P27/E27*F27 -> 112.68232 | Y27: =(H27+M27+N27+O27+P27)/E27*G27 -> 0 | Z27: =Q27+R27+S27+T27+U27+V27+W27+X27+Y27 -> 4645.1448 | AA27: =1800*F27/E27 -> 348.3871 | AB27: 0 | AC27: =IF(Z27>20000,200,IF(Z27>15000,150,0)) -> 0 | AD27: 0 | AE27: =AA27+AB27+AC27+AD27 -> 348.3871 | AF27: =ROUND(Z27-AE27,0) -> 4297 | AG27: =AA27*13/12 -> 377.41935 | AH27: 1000 | AI27: =Z27+AG27+AH27 -> 6022.5642 | AJ27: =26607*(F27+G27)/E27 -> 5149.7419 | AK27: =AJ27-AI27 -> -872.82226 | AL27: 22000
A28: =A27+1 -> 22 | B28: 11651 | C28: RUDRA MADHAB SENAPATI | D28: ELECTRICIAN | E28: 31 | F28: =VLOOKUP(B28,ATTENDANCE!$B$4:$AS$113,44,0) -> 0 | G28: 0 | H28: =I28+J28+K28+L28 -> 18421 | I28: 4722 | J28: 13699 | K28: 0 | L28: 0 | M28: =(I28+J28)*8.33% -> 1534.4693 | N28: =H28*4.93% -> 908.1553 | O28: =H28*3.29% -> 606.0509 | P28: =H28*2.88% -> 530.5248 | Q28: =I28/E28*F28 -> 0 | R28: =J28/E28*F28 -> 0 | S28: =+K28/E28*F28 -> 0 | T28: =L28/E28*F28 -> 0 | U28: =M28/E28*F28 -> 0 | V28: =N28/E28*F28 -> 0 | W28: =O28/E28*F28 -> 0 | X28: =P28/E28*F28 -> 0 | Y28: =(H28+M28+N28+O28+P28)/E28*G28 -> 0 | Z28: =Q28+R28+S28+T28+U28+V28+W28+X28+Y28 -> 0 | AA28: =1800*F28/E28 -> 0 | AB28: 0 | AC28: =IF(Z28>20000,200,IF(Z28>15000,150,0)) -> 0 | AD28: 0 | AE28: =AA28+AB28+AC28+AD28 -> 0 | AF28: =ROUND(Z28-AE28,0) -> 0 | AG28: =AA28*13/12 -> 0 | AH28: 1000 | AI28: =Z28+AG28+AH28 -> 1000 | AJ28: =26607*(F28+G28)/E28 -> 0 | AK28: =AJ28-AI28 -> -1000 | AL28: 20000
C29: ELECTRICIAN | E29: =SUM(E16:E28) -> 403 | F29: =SUM(F16:F28) -> 270 | G29: =SUM(G16:G28) -> 0 | H29: =SUM(H16:H28) -> 242434 | I29: =SUM(I16:I28) -> 61386 | J29: =SUM(J16:J28) -> 173468 | K29: =SUM(K16:K28) -> 7580 | L29: =SUM(L16:L28) -> 0 | ... AL29: =SUM(AL16:AL28) -> 284800
A30: =A28+1 -> 23 | B30: 11311 | C30: MOTUPALLI RAVI SANKARA DURGA | D30: BMS OPERATOR | E30: 31 | F30: =VLOOKUP(B30,ATTENDANCE!$B$4:$AS$113,44,0) -> 31 | G30: 0 | H30: =I30+J30+K30+L30 -> 18955 | I30: 4722 | J30: 13778 | K30: 455 | L30: 0 | M30: =(I30+J30)*8.33% -> 1541.05 | N30: =H30*4.93% -> 934.4815 | O30: =H30*3.29% -> 623.6195 | P30: =H30*2.88% -> 545.904 | Q30: =I30/E30*F30 -> 4722 | R30: =J30/E30*F30 -> 13778 | S30: =+K30/E30*F30 -> 455 | T30: =L30/E30*F30 -> 0 | U30: =M30/E30*F30 -> 1541.05 | V30: =N30/E30*F30 -> 934.4815 | W30: =O30/E30*F30 -> 623.6195 | X30: =P30/E30*F30 -> 545.904 | Y30: =(H30+M30+N30+O30+P30)/E30*G30 -> 0 | Z30: =Q30+R30+S30+T30+U30+V30+W30+X30+Y30 -> 22600.055 | AA30: =1800*F30/E30 -> 1800 | AB30: 0 | AC30: =IF(Z30>20000,200,IF(Z30>15000,150,0)) -> 200 | AD30: 0 | AE30: =AA30+AB30+AC30+AD30 -> 2000 | AF30: =ROUND(Z30-AE30,0) -> 20600 | AG30: =AA30*13/12 -> 1950 | AH30: 1000 | AI30: =Z30+AG30+AH30 -> 25550.055 | AJ30: =26472*(F30+G30)/E30 -> 26472 | AK30: =AJ30-AI30 -> 921.945 | AL30: 20600
A31: =A30+1 -> 24 | B31: 11376 | C31: J.CHATTYNYA | D31: BMS OPERATOR | E31: 31 | F31: =VLOOKUP(B31,ATTENDANCE!$B$4:$AS$113,44,0) -> 31 | G31: 0 | H31: =I31+J31+K31+L31 -> 20665 | I31: 4722 | J31: 13778 | K31: 2165 | L31: 0 | M31: =(I31+J31)*8.33% -> 1541.05 | N31: =H31*4.93% -> 1018.7845 | O31: =H31*3.29% -> 679.8785 | P31: =H31*2.88% -> 595.152 | Q31: =I31/E31*F31 -> 4722 | R31: =J31/E31*F31 -> 13778 | S31: =+K31/E31*F31 -> 2165 | T31: =L31/E31*F31 -> 0 | U31: =M31/E31*F31 -> 1541.05 | V31: =N31/E31*F31 -> 1018.7845 | W31: =O31/E31*F31 -> 679.8785 | X31: =P31/E31*F31 -> 595.152 | Y31: =(H31+M31+N31+O31+P31)/E31*G31 -> 0 | Z31: =Q31+R31+S31+T31+U31+V31+W31+X31+Y31 -> 24499.865 | AA31: =1800*F31/E31 -> 1800 | AB31: 0 | AC31: =IF(Z31>20000,200,IF(Z31>15000,150,0)) -> 200 | AD31: 0 | AE31: =AA31+AB31+AC31+AD31 -> 2000 | AF31: =ROUND(Z31-AE31,0) -> 22500 | AG31: =AA31*13/12 -> 1950 | AH31: 1000 | AI31: =Z31+AG31+AH31 -> 27449.865 | AJ31: =26472*(F31+G31)/E31 -> 26472 | AK31: =AJ31-AI31 -> -977.865 | AL31: 23000
A32: =A31+1 -> 25 | B32: 11 | C32: DAGE RAMA KRISHNA | D32: BMS OPERATOR | E32: 31 | F32: =VLOOKUP(B32,ATTENDANCE!$B$4:$AS$113,44,0) -> 28 | G32: 0 | H32: =I32+J32+K32+L32 -> 18002 | I32: 4722 | J32: 13280 | K32: 0 | L32: 0 | M32: =(I32+J32)*8.33% -> 1499.5666 | N32: =H32*4.93% -> 887.4986 | O32: =H32*3.29% -> 592.2658 | P32: =H32*2.88% -> 518.4576 | Q32: =I32/E32*F32 -> 4265.0323 | R32: =J32/E32*F32 -> 11994.839 | S32: =+K32/E32*F32 -> 0 | T32: =L32/E32*F32 -> 0 | U32: =M32/E32*F32 -> 1354.4473 | V32: =N32/E32*F32 -> 801.61164 | W32: =O32/E32*F32 -> 534.94975 | X32: =P32/E32*F32 -> 468.28428 | Y32: =(H32+M32+N32+O32+P32)/E32*G32 -> 0 | Z32: =Q32+R32+S32+T32+U32+V32+W32+X32+Y32 -> 19419.164 | AA32: =1800*F32/E32 -> 1625.8065 | AB32: 0 | AC32: =IF(Z32>20000,200,IF(Z32>15000,150,0)) -> 150 | AD32: 0 | AE32: =AA32+AB32+AC32+AD32 -> 1775.8065 | AF32: =ROUND(Z32-AE32,0) -> 17643 | AG32: =AA32*13/12 -> 1761.2903 | AH32: 1000 | AI32: =Z32+AG32+AH32 -> 22180.454 | AJ32: =26472*(F32+G32)/E32 -> 23910.194 | AK32: =AJ32-AI32 -> 1729.7393 | AL32: 23000
A33: =A32+1 -> 26 | B33: 10990 | C33: MUKESH SRICHANDAN | D33: BMS OPERATOR | E33: 31 | F33: =VLOOKUP(B33,ATTENDANCE!$B$4:$AS$113,44,0) -> 2 | G33: 0 | H33: =I33+J33+K33+L33 -> 19765 | I33: 4722 | J33: 13778 | K33: 1265 | L33: 0 | M33: =(I33+J33)*8.33% -> 1541.05 | N33: =H33*4.93% -> 974.4145 | O33: =H33*3.29% -> 650.2685 | P33: =H33*2.88% -> 569.232 | Q33: =I33/E33*F33 -> 304.64516 | R33: =J33/E33*F33 -> 888.90323 | S33: =+K33/E33*F33 -> 81.612903 | T33: =L33/E33*F33 -> 0 | U33: =M33/E33*F33 -> 99.422581 | V33: =N33/E33*F33 -> 62.865452 | W33: =O33/E33*F33 -> 41.952806 | X33: =P33/E33*F33 -> 36.724645 | Y33: =(H33+M33+N33+O33+P33)/E33*G33 -> 0 | Z33: =Q33+R33+S33+T33+U33+V33+W33+X33+Y33 -> 1516.1268 | AA33: =1800*F33/E33 -> 116.12903 | AB33: 0 | AC33: =IF(Z33>20000,200,IF(Z33>15000,150,0)) -> 0 | AD33: 0 | AE33: =AA33+AB33+AC33+AD33 -> 116.12903 | AF33: =ROUND(Z33-AE33,0) -> 1400 | AG33: =AA33*13/12 -> 125.80645 | AH33: 1000 | AI33: =Z33+AG33+AH33 -> 2641.9332 | AJ33: =26472*(F33+G33)/E33 -> 1707.871 | AK33: =AJ33-AI33 -> -934.06226 | AL33: 21500
C34: BMS Technician | E34: =SUM(E30:E33) -> 124 | F34: =SUM(F30:F33) -> 92 | G34: =SUM(G30:G33) -> 0 | H34: =SUM(H30:H33) -> 77387 | I34: =SUM(I30:I33) -> 18888 | J34: =SUM(J30:J33) -> 54614 | K34: =SUM(K30:K33) -> 3885 | L34: =SUM(L30:L33) -> 0 | ... AL34: =SUM(AL30:AL33) -> 88100
A35: =A33+1 -> 27 | B35: 11907 | C35: P.SAI SATHISH | D35: DG OPERATOR | E35: 31 | F35: =VLOOKUP(B35,ATTENDANCE!$B$4:$AS$113,44,0) -> 31 | G35: 0 | H35: =I35+J35+K35+L35 -> 17835 | I35: 4722 | J35: 13113 | K35: 0 | L35: 0 | M35: =(I35+J35)*8.33% -> 1485.6555 | N35: =H35*4.93% -> 879.2655 | O35: =H35*3.29% -> 586.7715 | P35: =H35*2.88% -> 513.648 | Q35: =I35/E35*F35 -> 4722 | R35: =J35/E35*F35 -> 13113 | S35: =+K35/E35*F35 -> 0 | T35: =L35/E35*F35 -> 0 | U35: =M35/E35*F35 -> 1485.6555 | V35: =N35/E35*F35 -> 879.2655 | W35: =O35/E35*F35 -> 586.7715 | X35: =P35/E35*F35 -> 513.648 | Y35: =(H35+M35+N35+O35+P35)/E35*G35 -> 0 | Z35: =Q35+R35+S35+T35+U35+V35+W35+X35+Y35 -> 21300.341 | AA35: =1800*F35/E35 -> 1800 | AB35: 0 | AC35: =IF(Z35>20000,200,IF(Z35>15000,150,0)) -> 200 | AD35: 0 | AE35: =AA35+AB35+AC35+AD35 -> 2000 | AF35: =ROUND(Z35-AE35,0) -> 19300 | AG35: =AA35*13/12 -> 1950 | AH35: 1000 | AI35: =Z35+AG35+AH35 -> 24250.341 | AJ35: =26472*(F35+G35)/E35 -> 26472 | AK35: =AJ35-AI35 -> 2221.6595 | AL35: 19300
A36: =A35+1 -> 28 | B36: 11273 | C36: P CHANDRA SHEKAR PATRA | D36: DG OPERATOR | E36: 31 | F36: =VLOOKUP(B36,ATTENDANCE!$B$4:$AS$113,44,0) -> 31 | G36: 0 | H36: =I36+J36+K36+L36 -> 19765 | I36: 4722 | J36: 13778 | K36: 1265 | L36: 0 | M36: =(I36+J36)*8.33% -> 1541.05 | N36: =H36*4.93% -> 974.4145 | O36: =H36*3.29% -> 650.2685 | P36: =H36*2.88% -> 569.232 | Q36: =I36/E36*F36 -> 4722 | R36: =J36/E36*F36 -> 13778 | S36: =+K36/E36*F36 -> 1265 | T36: =L36/E36*F36 -> 0 | U36: =M36/E36*F36 -> 1541.05 | V36: =N36/E36*F36 -> 974.4145 | W36: =O36/E36*F36 -> 650.2685 | X36: =P36/E36*F36 -> 569.232 | Y36: =(H36+M36+N36+O36+P36)/E36*G36 -> 0 | Z36: =Q36+R36+S36+T36+U36+V36+W36+X36+Y36 -> 23499.965 | AA36: =1800*F36/E36 -> 1800 | AB36: 0 | AC36: =IF(Z36>20000,200,IF(Z36>15000,150,0)) -> 200 | AD36: 0 | AE36: =AA36+AB36+AC36+AD36 -> 2000 | AF36: =ROUND(Z36-AE36,0) -> 21500 | AG36: =AA36*13/12 -> 1950 | AH36: 1000 | AI36: =Z36+AG36+AH36 -> 26449.965 | AJ36: =26472*(F36+G36)/E36 -> 26472 | AK36: =AJ36-AI36 -> 22.035 | AL36: 21500
A37: =A36+1 -> 29 | B37: 11000 | C37: ALLAUDDIN MAINODDIN KHAJURE | D37: DG OPERATOR | E37: 31 | F37: =VLOOKUP(B37,ATTENDANCE!$B$4:$AS$113,44,0) -> 31 | G37: 0 | H37: =I37+J37+K37+L37 -> 23779.5 | I37: 4722 | J37: 13778 | K37: 5279.5 | L37: 0 | M37: =(I37+J37)*8.33% -> 1541.05 | N37: =H37*4.93% -> 1172.3293 | O37: =H37*3.29% -> 782.34555 | P37: =H37*2.88% -> 684.8496 | Q37: =I37/E37*F37 -> 4722 | R37: =J37/E37*F37 -> 13778 | S37: =+K37/E37*F37 -> 5279.5 | T37: =L37/E37*F37 -> 0 | U37: =M37/E37*F37 -> 1541.05 | V37: =N37/E37*F37 -> 1172.3293 | W37: =O37/E37*F37 -> 782.34555 | X37: =P37/E37*F37 -> 684.8496 | Y37: =(H37+M37+N37+O37+P37)/E37*G37 -> 0 | Z37: =Q37+R37+S37+T37+U37+V37+W37+X37+Y37 -> 27960.075 | AA37: =1800*F37/E37 -> 1800 | AB37: 0 | AC37: =IF(Z37>20000,200,IF(Z37>15000,150,0)) -> 200 | AD37: 0 | AE37: =AA37+AB37+AC37+AD37 -> 2000 | AF37: =ROUND(Z37-AE37,0) -> 25960 | AG37: =AA37*13/12 -> 1950 | AH37: 1000 | AI37: =Z37+AG37+AH37 -> 30910.075 | AJ37: =26472*(F37+G37)/E37 -> 26472 | AK37: =AJ37-AI37 -> -4438.0745 | AL37: 25960
A38: =A37+1 -> 30 | B38: 11551 | C38: RAUPYA PRAKASH | D38: DG OPERATOR | E38: 31 | F38: =VLOOKUP(B38,ATTENDANCE!$B$4:$AS$113,44,0) -> 31 | G38: 0 | H38: =I38+J38+K38+L38 -> 18775 | I38: 4722 | J38: 13778 | K38: 275 | L38: 0 | M38: =(I38+J38)*8.33% -> 1541.05 | N38: =H38*4.93% -> 925.6075 | O38: =H38*3.29% -> 617.6975 | P38: =H38*2.88% -> 540.72 | Q38: =I38/E38*F38 -> 4722 | R38: =J38/E38*F38 -> 13778 | S38: =+K38/E38*F38 -> 275 | T38: =L38/E38*F38 -> 0 | U38: =M38/E38*F38 -> 1541.05 | V38: =N38/E38*F38 -> 925.6075 | W38: =O38/E38*F38 -> 617.6975 | X38: =P38/E38*F38 -> 540.72 | Y38: =(H38+M38+N38+O38+P38)/E38*G38 -> 0 | Z38: =Q38+R38+S38+T38+U38+V38+W38+X38+Y38 -> 22400.075 | AA38: =1800*F38/E38 -> 1800 | AB38: 0 | AC38: =IF(Z38>20000,200,IF(Z38>15000,150,0)) -> 200 | AD38: 0 | AE38: =AA38+AB38+AC38+AD38 -> 2000 | AF38: =ROUND(Z38-AE38,0) -> 20400 | AG38: =AA38*13/12 -> 1950 | AH38: 1000 | AI38: =Z38+AG38+AH38 -> 25350.075 | AJ38: =26472*(F38+G38)/E38 -> 26472 | AK38: =AJ38-AI38 -> 1121.925 | AL38: 20400
C39: DG OPERATOR | E39: =SUM(E35:E38) -> 124 | F39: =SUM(F35:F38) -> 124 | G39: =SUM(G35:G38) -> 0 | H39: =SUM(H35:H38) -> 80154.5 | I39: =SUM(I35:I38) -> 18888 | J39: =SUM(J35:J38) -> 54447 | K39: =SUM(K35:K38) -> 6819.5 | L39: =SUM(L35:L38) -> 0 | ... AL39: =SUM(AL35:AL38) -> 87160
A40: =A38+1 -> 31 | B40: 10991 | C40: JOGENDRA SETHI | D40: HVAC OPERATOR | E40: 31 | F40: =VLOOKUP(B40,ATTENDANCE!$B$4:$AS$113,44,0) -> 31 | G40: 0 | H40: =I40+J40+K40+L40 -> 23815.4 | I40: 4722 | J40: 13778 | K40: 5315.4 | L40: 0 | M40: =(I40+J40)*8.33% -> 1541.05 | N40: =H40*4.93% -> 1174.0992 | O40: =H40*3.29% -> 783.52666 | P40: =H40*2.88% -> 685.88352 | Q40: =I40/E40*F40 -> 4722 | R40: =J40/E40*F40 -> 13778 | S40: =+K40/E40*F40 -> 5315.4 | T40: =L40/E40*F40 -> 0 | U40: =M40/E40*F40 -> 1541.05 | V40: =N40/E40*F40 -> 1174.0992 | W40: =O40/E40*F40 -> 783.52666 | X40: =P40/E40*F40 -> 685.88352 | Y40: =(H40+M40+N40+O40+P40)/E40*G40 -> 0 | Z40: =Q40+R40+S40+T40+U40+V40+W40+X40+Y40 -> 27999.959 | AA40: =1800*F40/E40 -> 1800 | AB40: 0 | AC40: =IF(Z40>20000,200,IF(Z40>15000,150,0)) -> 200 | AD40: 0 | AE40: =AA40+AB40+AC40+AD40 -> 2000 | AF40: =ROUND(Z40-AE40,0) -> 26000 | AG40: =AA40*13/12 -> 1950 | AH40: 1000 | AI40: =Z40+AG40+AH40 -> 30949.959 | AJ40: =26552*(F40+G40)/E40 -> 26552 | AK40: =AJ40-AI40 -> -4397.9594 | AL40: 26000
A41: =A40+1 -> 32 | B41: 11476 | C41: HARISH KHAN | D41: HVAC OPERATOR | E41: 31 | F41: =VLOOKUP(B41,ATTENDANCE!$B$4:$AS$113,44,0) -> 23 | G41: 0 | H41: =I41+J41+K41+L41 -> 19900 | I41: 4722 | J41: 13778 | K41: 1400 | L41: 0 | M41: =(I41+J41)*8.33% -> 1541.05 | N41: =H41*4.93% -> 981.07 | O41: =H41*3.29% -> 654.71 | P41: =H41*2.88% -> 573.12 | Q41: =I41/E41*F41 -> 3503.4194 | R41: =J41/E41*F41 -> 10222.387 | S41: =+K41/E41*F41 -> 1038.7097 | T41: =L41/E41*F41 -> 0 | U41: =M41/E41*F41 -> 1143.3597 | V41: =N41/E41*F41 -> 727.89065 | W41: =O41/E41*F41 -> 485.75258 | X41: =P41/E41*F41 -> 425.21806 | Y41: =(H41+M41+N41+O41+P41)/E41*G41 -> 0 | Z41: =Q41+R41+S41+T41+U41+V41+W41+X41+Y41 -> 17546.737 | AA41: =1800*F41/E41 -> 1335.4839 | AB41: 0 | AC41: =IF(Z41>20000,200,IF(Z41>15000,150,0)) -> 150 | AD41: 0 | AE41: =AA41+AB41+AC41+AD41 -> 1485.4839 | AF41: =ROUND(Z41-AE41,0) -> 16061 | AG41: =AA41*13/12 -> 1446.7742 | AH41: 1000 | AI41: =Z41+AG41+AH41 -> 19993.511 | AJ41: =26552*(F41+G41)/E41 -> 19699.871 | AK41: =AJ41-AI41 -> -293.64032 | AL41: 21650
...

Sheet FULL
AB2: grooming deduction
A3: MIDAS-B1&B2 FOR THE MONTH OF APR 2025 | H3: ACTUAL COMPONENTS | P3: EARNING COMPONENTS | Y3: DEDUCTIONS
A4: S.NO | B4: EMP CODE | C4: EMPLOYEE NAME | D4: Designation | E4: ACTUAL DAYS | F4: NET PAID DAYS | G4: EXTRA DEPLOYMENT | H4: GROSS SALARY | I4: BASIC | J4: DA | K4: OTHER ALLOWANCE | L4: Bonus 8.33% (Basic + DA) | M4: Leave Wage (EL @ 18days) 4.93% | N4: Leave Wage (CL @ 12days) 3.29% | O4: National Holiday and Festival Holidays 10 days @2.88% | P4: BASIC | Q4: DA | R4: OTHER ALLOWANCE | S4: Bonus 8.33% (Basic + DA) | T4: Leave Wage (EL @ 18days) 4.93% | U4: Leave Wage (CL @ 12days) 3.29% | V4: National Holiday and Festival Holidays 10 days @2.88% | W4: Extra Deployment Amount | X4: GROSS EARNINGS | Y4: EMPLOYEE PF@12% | Z4: EMPLOYEE ESI@0.75% | AA4: PROFESSION TAX | AB4: Advances | AC4: TOTAL DEDUCTIONS | AD4: NET PAY | AE4: EMPLOYER PF@13% | AF4: EMPLOYER ESI @3.25% / INSURANCE | AG4: CTC
A5: 1 | B5: 11029 | C5: SUDHIR KUMAR RAUTARAY | D5: TECHNICAL EXECUTIVE | E5: 30 | F5: 30 | G5: 0 | H5: =I5+J5+K5 -> 30365 | I5: 5557 | J5: 9050 | K5: 15758 | L5: =(I5+J5)*8.33% -> 1216.7631 | M5: =H5*4.93% -> 1496.9945 | N5: =H5*3.29% -> 999.0085 | O5: =H5*2.88% -> 874.512 | P5: =I5/E5*F5 -> 5557 | Q5: =J5/E5*F5 -> 9050 | R5: =K5/E5*F5 -> 15758 | S5: =L5/E5*F5 -> 1216.7631 | T5: =M5/E5*F5 -> 1496.9945 | U5: =N5/E5*F5 -> 999.0085 | V5: =O5/E5*F5 -> 874.512 | W5: =(H5+L5+M5+N5+O5)/E5*G5 -> 0 | X5: =P5+Q5+R5+S5+T5+U5+V5+W5 -> 34952.278 | Y5: =(P5+Q5)*12% -> 1752.84 | Z5: 0 | AA5: =IF(X5>20000,200,IF(X5>15000,150,0)) -> 200 | AC5: =Y5+Z5+AA5+AB5 -> 1952.84 | AD5: =ROUND(X5-AC5,0) -> 32999 | AE5: =(P5+Q5)*13% -> 1898.91 | AF5: 800 | AG5: =X5+AE5+AF5 -> 37651.188 | AH5: 36834
C6: TECHNICAL EXECUTIVE | E6: =SUM(E5) -> 30 | F6: =SUM(F5) -> 30 | G6: =SUM(G5) -> 0 | H6: =SUM(H5) -> 30365 | I6: =SUM(I5) -> 5557 | J6: =SUM(J5) -> 9050 | K6: =SUM(K5) -> 15758 | L6: =SUM(L5) -> 1216.7631 | ... AH6: =SUM(AH5) -> 36834 | AI6: =AH6-AG6 -> -817.1881
A7: 2 | B7: 10984 | C7: K.RAJYALAKSHMI | D7: TECHNICAL SUPERVISOR | E7: 30 | F7: 30 | G7: 0 | H7: =I7+J7+K7 -> 22687 | I7: 4722 | J7: 9050 | K7: 8915 | L7: =(I7+J7)*8.33% -> 1147.2076 | M7: =H7*4.93% -> 1118.4691 | N7: =H7*3.29% -> 746.4023 | O7: =H7*2.88% -> 653.3856 | P7: =I7/E7*F7 -> 4722 | Q7: =J7/E7*F7 -> 9050 | R7: =K7/E7*F7 -> 8915 | S7: =L7/E7*F7 -> 1147.2076 | T7: =M7/E7*F7 -> 1118.4691 | U7: =N7/E7*F7 -> 746.4023 | V7: =O7/E7*F7 -> 653.3856 | W7: =(H7+L7+M7+N7+O7)/E7*G7 -> 0 | X7: =P7+Q7+R7+S7+T7+U7+V7+W7 -> 26352.465 | Y7: =(P7+Q7)*12% -> 1652.64 | Z7: 0 | AA7: =IF(X7>20000,200,IF(X7>15000,150,0)) -> 200 | AC7: =Y7+Z7+AA7+AB7 -> 1852.64 | AD7: =ROUND(X7-AC7,0) -> 24500 | AE7: =(P7+Q7)*13% -> 1790.36 | AF7: 800 | AG7: =X7+AE7+AF7 -> 28942.825 | AH7: 28930 | AI7: =AH7-AG7 -> -12.8246
A8: =A7+1 -> 3 | B8: 10986 | C8: KHIROD DAS | D8: TECHNICAL SUPERVISOR | E8: 30 | F8: 30 | G8: 0 | H8: =I8+J8+K8 -> 23896 | I8: 4722 | J8: 9050 | K8: 10124 | L8: =(I8+J8)*8.33% -> 1147.2076 | M8: =H8*4.93% -> 1178.0728 | N8: =H8*3.29% -> 786.1784 | O8: =H8*2.88% -> 688.2048 | P8: =I8/E8*F8 -> 4722 | Q8: =J8/E8*F8 -> 9050 | R8: =K8/E8*F8 -> 10124 | S8: =L8/E8*F8 -> 1147.2076 | T8: =M8/E8*F8 -> 1178.0728 | U8: =N8/E8*F8 -> 786.1784 | V8: =O8/E8*F8 -> 688.2048 | W8: =(H8+L8+M8+N8+O8)/E8*G8 -> 0 | X8: =P8+Q8+R8+S8+T8+U8+V8+W8 -> 27695.664 | Y8: =(P8+Q8)*12% -> 1652.64 | Z8: 0 | AA8: =IF(X8>20000,200,IF(X8>15000,150,0)) -> 200 | AC8: =Y8+Z8+AA8+AB8 -> 1852.64 | AD8: =ROUND(X8-AC8,0) -> 25843 | AE8: =(P8+Q8)*13% -> 1790.36 | AF8: 800 | AG8: =X8+AE8+AF8 -> 30286.024 | AH8: 28930 | AI8: =AH8-AG8 -> -1356.0236
A9: =A8+1 -> 4 | B9: 10989 | C9: NAGENDRA | D9: TECHNICAL SUPERVISOR | E9: 30 | F9: 30 | G9: 0 | H9: =I9+J9+K9 -> 22417 | I9: 4722 | J9: 9050 | K9: 8645 | L9: =(I9+J9)*8.33% -> 1147.2076 | M9: =H9*4.93% -> 1105.1581 | N9: =H9*3.29% -> 737.5193 | O9: =H9*2.88% -> 645.6096 | P9: =I9/E9*F9 -> 4722 | Q9: =J9/E9*F9 -> 9050 | R9: =K9/E9*F9 -> 8645 | S9: =L9/E9*F9 -> 1147.2076 | T9: =M9/E9*F9 -> 1105.1581 | U9: =N9/E9*F9 -> 737.5193 | V9: =O9/E9*F9 -> 645.6096 | W9: =(H9+L9+M9+N9+O9)/E9*G9 -> 0 | X9: =P9+Q9+R9+S9+T9+U9+V9+W9 -> 26052.495 | Y9: =(P9+Q9)*12% -> 1652.64 | Z9: 0 | AA9: =IF(X9>20000,200,IF(X9>15000,150,0)) -> 200 | AC9: =Y9+Z9+AA9+AB9 -> 1852.64 | AD9: =ROUND(X9-AC9,0) -> 24200 | AE9: =(P9+Q9)*13% -> 1790.36 | AF9: 800 | AG9: =X9+AE9+AF9 -> 28642.855 | AH9: 28930 | AI9: =AH9-AG9 -> 287.1454
